Workbook

Sheet DASHBOARD
B2: Colo Ritmo · Hospital da Criança de Brasília
B3: Painel da escala · Outubro de 2026
B5: Toda contagem aqui é fórmula das abas mensais — digitou um código na escala, este painel se refaz sozinho.
B8: O mês que vai publicar · Outubro
B9: BURACOS DE COBERTURA NO MÊS | E9: DIAS COMPLETOS | G9: ALERTAS DE 18H | I9: FORA DA META | K9: SEMANAS COM BH ≠ 0 | M9: HORAS NOTURNAS
B10: =IF(COUNTA(OUT!$I$8:$AM$73)>0,SUMPRODUCT(((OUT!$I$75:$AM$75+OUT!$I$76:$AM$76+OUT!$I$77:$AM$77)>0)*OUT!$I$78:$AM$78)+SUMPRODUCT(((OUT!$I$75:$AM$75+OUT!$I$76:$AM$76+OUT!$I$77:$AM$77)>0)*OUT!$I$79:$AM$79)+SUMPRODUCT(((OUT!$I$75:$AM$75+OUT!$I$76:$AM$76+OUT!$I$77:$AM$77)>0)*OUT!$I$80:$AM$80),"") | E10: =IF(COUNTA(OUT!$I$8:$AM$73)>0,SUMPRODUCT(((OUT!$I$75:$AM$75+OUT!$I$76:$AM$76+OUT!$I$77:$AM$77)>0)*(OUT!$I$78:$AM$78+OUT!$I$79:$AM$79+OUT!$I$80:$AM$80=0)*(OUT!$I$78:$AM$78<>"")),"")&"/"&SUMPRODUCT(((OUT!$I$75:$AM$75+OUT!$I$76:$AM$76+OUT!$I$77:$AM$77)>0)*1) | G10: =SUM(OUT!$BL$8:$BL$73) | I10: =SUMPRODUCT(--(ABS(OUT!$BK$8:$BK$73)>12)) | K10: =SUMPRODUCT((OUT!$AU$8:$AU$73<>"")*(OUT!$AU$8:$AU$73<>0))+SUMPRODUCT((OUT!$AW$8:$AW$73<>"")*(OUT!$AW$8:$AW$73<>0))+SUMPRODUCT((OUT!$AY$8:$AY$73<>"")*(OUT!$AY$8:$AY$73<>0))+SUMPRODUCT((OUT!$BA$8:$BA$73<>"")*(OUT!$BA$8:$BA$73<>0))+SUMPRODUCT((OUT!$BC$8:$BC$73<>"")*(OUT!$BC$8:$BC$73<>0))+SUMPRODUCT((OUT!$BE$8:$BE$73<>"")*(OUT!$BE$8:$BE$73<>0)) | M10: =(COUNTIF(OUT!$I$8:$AM$73,"N")+COUNTIF(OUT!$I$8:$AM$73,"N+"))*7+COUNTIF(OUT!$I$8:$AM$73,"NT")*3
B12: soma de tudo que falta pro mínimo, somando os três turnos e os 31 dias | E12: dias em que os três turnos bateram o mínimo | G12: o alvo é zero · art. 66 CLT | I12: pessoas com mais de 12h de desvio, pra cima ou pra baixo | K12: pessoa-semanas fora do alvo · BHP (+) ou BHN/faltou (−) | M12: janela 22h–05h · insumo do adicional noturno
B13: Outubro é a versão da Mari (Sheet vivo, 01/09) com as correções da checagem dela e do Marcos — cada mudança está na aba CHECAGEM OUT. Janeiro a setembro vêm das grades do grupo. Nada aqui é proposta do gerador.
B14: O ano · Para comparar
B15: As regras duras apertaram junto com a mudança de abril, e funcionou: os alertas de 18h caíram de ~15 por mês para ~2.
B17: Mês | C17: Alertas 18h | D17: Buracos | E17: Dias completos | F17: Manhã | G17: Tarde | H17: Noite | I17: Horas noturnas
B18: Jan | C18: ='DADOS DASH'!B5 | D18: ='DADOS DASH'!C5 | E18: ='DADOS DASH'!D5 | F18: ='DADOS DASH'!E5 | G18: ='DADOS DASH'!F5 | H18: ='DADOS DASH'!G5 | I18: ='DADOS DASH'!I5
B19: Fev | C19: ='DADOS DASH'!B6 | D19: ='DADOS DASH'!C6 | E19: ='DADOS DASH'!D6 | F19: ='DADOS DASH'!E6 | G19: ='DADOS DASH'!F6 | H19: ='DADOS DASH'!G6 | I19: ='DADOS DASH'!I6
B20: Mar | C20: ='DADOS DASH'!B7 | D20: ='DADOS DASH'!C7 | E20: ='DADOS DASH'!D7 | F20: ='DADOS DASH'!E7 | G20: ='DADOS DASH'!F7 | H20: ='DADOS DASH'!G7 | I20: ='DADOS DASH'!I7
B21: Abr | C21: ='DADOS DASH'!B8 | D21: ='DADOS DASH'!C8 | E21: ='DADOS DASH'!D8 | F21: ='DADOS DASH'!E8 | G21: ='DADOS DASH'!F8 | H21: ='DADOS DASH'!G8 | I21: ='DADOS DASH'!I8
B22: Mai | C22: ='DADOS DASH'!B9 | D22: ='DADOS DASH'!C9 | E22: ='DADOS DASH'!D9 | F22: ='DADOS DASH'!E9 | G22: ='DADOS DASH'!F9 | H22: ='DADOS DASH'!G9 | I22: ='DADOS DASH'!I9
B23: Jun | C23: ='DADOS DASH'!B10 | D23: ='DADOS DASH'!C10 | E23: ='DADOS DASH'!D10 | F23: ='DADOS DASH'!E10 | G23: ='DADOS DASH'!F10 | H23: ='DADOS DASH'!G10 | I23: ='DADOS DASH'!I10
B24: Jul | C24: ='DADOS DASH'!B11 | D24: ='DADOS DASH'!C11 | E24: ='DADOS DASH'!D11 | F24: ='DADOS DASH'!E11 | G24: ='DADOS DASH'!F11 | H24: ='DADOS DASH'!G11 | I24: ='DADOS DASH'!I11
B25: Ago | C25: ='DADOS DASH'!B12 | D25: ='DADOS DASH'!C12 | E25: ='DADOS DASH'!D12 | F25: ='DADOS DASH'!E12 | G25: ='DADOS DASH'!F12 | H25: ='DADOS DASH'!G12 | I25: ='DADOS DASH'!I12
B26: Set | C26: ='DADOS DASH'!B13 | D26: ='DADOS DASH'!C13 | E26: ='DADOS DASH'!D13 | F26: ='DADOS DASH'!E13 | G26: ='DADOS DASH'!F13 | H26: ='DADOS DASH'!G13 | I26: ='DADOS DASH'!I13
B27: Out | C27: ='DADOS DASH'!B14 | D27: ='DADOS DASH'!C14 | E27: ='DADOS DASH'!D14 | F27: ='DADOS DASH'!E14 | G27: ='DADOS DASH'!F14 | H27: ='DADOS DASH'!G14 | I27: ='DADOS DASH'!I14
B28: Nov | C28: ='DADOS DASH'!B15 | D28: ='DADOS DASH'!C15 | E28: ='DADOS DASH'!D15 | F28: ='DADOS DASH'!E15 | G28: ='DADOS DASH'!F15 | H28: ='DADOS DASH'!G15 | I28: ='DADOS DASH'!I15
B29: Dez | C29: ='DADOS DASH'!B16 | D29: ='DADOS DASH'!C16 | E29: ='DADOS DASH'!D16 | F29: ='DADOS DASH'!E16 | G29: ='DADOS DASH'!F16 | H29: ='DADOS DASH'!G16 | I29: ='DADOS DASH'!I16

Sheet LEIA-ME
A1: Escala UTI HCB · 2026 — V3
A3: O que é
B4: O ano inteiro num arquivo: 12 abas mensais com a escala real, o painel comparativo do ano, a tradução pros códigos do Senior e o validador das regras que são lei. Tudo o que é contagem é fórmula — digitou o código na aba do mês, a cobertura, a carga horária, o saldo e os alertas se refazem sozinhos.
A6: Legenda dos códigos
A7: código | B7: turno | C7: horário | D7: horas | E7: Senior
A8: M | B8: manhã | C8: 07–13h | D8: 6 | E8: 2
A9: T | B9: tarde | C9: 13–19h | D9: 6 | E9: 239
A10: D | B10: dia 12h | C10: 07–19h | D10: 12 | E10: 40
A11: N | B11: noite 12h | C11: 19–07h | D11: 12 | E11: 41
A12: NT | B12: noitinha | C12: 19–01h | D12: 6 | E12: 349
A13: C | B13: 10h chefia | C13: 8–12 + 13–19h | D13: 10 | E13: 47
A14: A | B14: administrativo | C14: 8h diurno | D14: 8 | E14: 11
A15: J | B15: 5h Janaina | C15: 08–13h | D15: 5 | E15: 78
A16: CEP | B16: 4h CEP | C16: 08–12h | D16: 4 | E16: 6
A17: CP | B17: CP · cuidados paliativos | C17: 07–13h | D17: 6 | E17: —
A18: CRO | B18: CRO · ambulatório | C18: 13–19h | D18: 6 | E18: —
A19: M+ | B19: manhã BHP | C19: 07–13h · banco | D19: 6 | E19: —
... A24: Dt+ | B24: dia · tarde é BHP | C24: 07–19h | D24: 12 | E24: 2
A25: M- | B25: BHN da manhã | C25: dispensa | D25: — | E25: 2
A26: T- | B26: BHN da tarde | C26: dispensa | D26: — | E26: 239
A27: D- | B27: BHN do dia | C27: dispensa | D27: — | E27: 40
A28: N- | B28: BHN da noite | C28: dispensa | D28: — | E28: 41
A29: Tm- | B29: tarde · manhã é BHN | C29: 13–19h | D29: 6 | E29: 40
A30: Mt- | B30: manhã · tarde é BHN | C30: 07–13h | D30: 6 | E30: 40
A31: FE | B31: férias | C31: — | D31: — | E31: Férias
A32: LM | B32: licença | C32: — | D32: — | E32: LM
A33: AB | B33: abono niver | C33: — | D33: — | E33: —
A34: Antigos | B34: Até abril de 2026 os códigos eram outros: 110 = M (manhã) · 82 = D (dia 12h) · 83 = N (noite 12h) · 10 = J (5h, virou 78). A mudança de abril passou a usar 2/40/41.
A35: Banco | B35: Código com + é BHP: a pessoa trabalha a MAIS e a hora fica no banco — o Senior não recebe esse plantão. Código com − é BHN: dispensa paga pelo banco — a pessoa não vem, mas o Senior recebe o plantão normal. Dm+ é um dia inteiro em que só a manhã é BHP; Tm- é uma tarde trabalhada com a manhã dispensada.
A37: As abas
A38: CADASTRO | B38: Quem é quem: carga horária, restrições duras, sexta-noite e fds extra. É a fonte dos nomes de todas as abas mensais.
A39: CONFIG | B39: As regras como dado: cobertura mínima, cota de fds em mês com férias, tabela de códigos e as regras duras com o artigo da CLT. Mudou aqui, mudou na planilha toda.
A40: JAN a DEZ | B40: A escala: matriz médico × dia, com filtro no cabeçalho pra ordenar (veja “Ordenar” abaixo). A semana fecha NO DOMINGO, então todo mês aparece com as semanas completas: as primeiras colunas trazem o fim do mês anterior e as últimas trazem os dias do mês seguinte até o domingo que fecha a última semana. Esses dias vizinhos são fórmula da aba deles — pra editar, use a aba do mês dono do dia. À direita, por pessoa, PRIMEIRO as semanas: Sem 1..6 = horas de cada semana civil (o intervalo de datas está em cima) e, ao lado de cada uma, BH = horas − alvo semanal da pessoa (+ é BHP e fica areia, − é BHN/faltou e fica coral; zero é semana fechada). Depois: carga do mês, fds, sexta-noite, feriado, meta, saldo e os alertas de jornada. No rodapé, a lotação de cada turno e quanto falta pro mínimo.
A41: Ordenar | B41: Cada aba mensal tem um FILTRO no cabeçalho (ícone de funil): clique no funil de “Médico” e ordene de A a Z, ou no de “Grupo” para ver coordenação → rotina → staff. A coluna “Nº” volta à ordem original. A planilha foi preparada para isso: toda fórmula acha cada pessoa PELO NOME, em qualquer ordem — ordenar pelo funil não quebra nada. Só não use “Classificar intervalo” numa seleção parcial, que aí as linhas se separam das colunas.
A42: OUT · DIA A DIA | B42: O mês em formato calendário: por dia e por turno, quem está onde, e a cobertura. Abre na segunda-feira da semana do dia 1º e fecha no domingo da última semana — os dias dos meses vizinhos aparecem acinzentados, só para leitura. É fórmula da aba do mês — trocou um plantão no dropdown, o dia a dia se refaz. Bom pra bater o olho e perceber o que está esquisito.
A43: PAINEL ANO | B43: O comparativo do ano: saldo, fds, sexta-noite e feriado de cada pessoa mês a mês, com acumulado. Onde existe a contagem manual antiga, ela aparece ao lado pra conferência.
A44: SENIOR | B44: Escolha o mês em B1 e a matriz inteira sai traduzida nos códigos do RH, pronta pra lançar.
A45: VALIDADOR | B45: O que fere regra dura, separado em ESTRUTURAL (é a forma do contrato, decisão de política) e PONTUAL (erro daquele mês).
A46: CHECAGEM OUT | B46: A checagem de outubro feita por Marcos e Mari: as regras que ela revelou, cada célula que mudou (estava → ficou, por quê) e o que foi verificado sem mudar.
A48: De onde vem cada mês — leia antes de comparar
...

Sheet CADASTRO
A1: Cadastro · Quem é quem
A2: 66 pessoas ativas
A3: Médico | B3: Nome completo | C3: CH | D3: Grupo | E3: Restrições duras | F3: Sexta-noite | G3: FDS extra | H3: Observações | I3: Alvo/sem
A4: Fred | B4: Frederico Pires | C4: 36 | D4: chefia | E4: coordenação: seg+ter 10h de chefia (47), qua+qui manhã | F4: não | G4: não | H4: o 47 é lançado pela coordenação · CH não entra nas contagens de plantão | I4: 36
A5: Milena | B5: Milena | C5: 36 | D5: chefia | E5: coordenação: seg/ter/qua manhã, qui 10h de chefia (47) | F5: não | G5: não | H5: o 47 é lançado pela coordenação | I5: 36
A6: Pabdo | B6: Paula Abdo | C6: 36 | D6: chefia | E6: manhãs seg–sex | F6: não | G6: não | H6: aniversário 29/10, sem folga | I6: 36
A7: MSalomão | B7: Marina Salomão | C7: 40 | D7: chefia | E7: manhãs seg–sex · D às quintas · N de domingo no rodízio de fds 15/15 com Vinicius · alvo 42h/semana com UMA semana de 36h no mês | F7: não | G7: não | H7: folga 12/10 (pedido individual) · NÃO sexta tarde | I7: 42
A8: DebAlves | B8: Deborah Alves | C8: 40 | D8: chefia | E8: manhãs e tardes seg–sex, D pra completar (cobre o gargalo das tardes) · alvo 42h/semana com UMA semana de 36h no mês | F8: não | G8: não | I8: 42
A9: Vinicius | B9: Vinicius Bezerra | C9: 36 | D9: chefia | E9: manhãs seg–sex · N de sábado no rodízio 15/15 com Murilo · fds 15/15 com MSalomão | F9: não | G9: sim | H9: FÉRIAS 12–26/10 — volta ter 27/10 (semana de retorno: alvo 30h) | I9: 36
A10: Amelio | B10: Fernanda Amelio | C10: 36 | D10: chefia | E10: manhãs seg–sex e D diurnos (inclusive fds) · SEM NOTURNOS (atestado) | F10: não | G10: não | H10: fora 24–31/10 (BHN) — compensa com BHP em 03 e 17/10 | I10: 36
A11: Murilo | B11: Murilo | C11: 36 | D11: rotina | E11: rotina onco: manhãs seg–sex · N de sábado no rodízio 15/15 com Vinicius | F11: não | G11: não | I11: 36
A12: Janaina | B12: Janaina Rabelo | C12: 30 | D12: 30h | E12: SÓ 8–13h (código 78); sem noturnos; seg–sáb | F12: não | G12: não | H12: é sempre a 10ª da manhã de sábado; NUNCA domingo | I12: 30
A13: Aline | B13: Aline Saliba | C13: 40 | D13: 36h | E13: CEP 4h toda semana: 1ª terça manhã do mês (reunião); demais semanas seg ou qui | F13: não | G13: sim | H13: 36 assist + 4 CEP (alvo semanal 40) · FÉRIAS 19/10–02/11 | I13: 40
A14: CaAbreu | B14: Camila Abreu | C14: 36 | D14: 36h | E14: fixa qua dia (+seg dia); NÃO qui noite | F14: não | G14: sim | I14: 36
A15: Danielle | B15: Danielle Tanajura | C15: 36 | D15: 36h | E15: fixa qua noite (+qui noite); só noites | F15: não | G15: não | H15: não lançar sexta-noite (já fez muitas) | I15: 36
A16: Fabiula | B16: Fabiula Czameski | C16: 36 | D16: 36h | E16: só noites; ter/qua/qui alternando com ter/qua/dom | F16: sim | G16: não | I16: 36
A17: Isabella | B17: Isabella Mazzaro | C17: 36 | D17: 36h | E17: fixo sex dia; NÃO qua noite, NÃO qui noite; evitar sáb noite | F17: sim | G17: não | H17: INVERTEU em out: não pode mais sextas | I17: 36
A18: JuBrito | B18: Julliana Brito | C18: 30 | D18: 30h | E18: fixa ter dia, qua manhã, qui dia, sex manhã; NÃO segundas (Sobradinho) | F18: não | G18: não | H18: CH 30h CONFIRMADO (era 36) · +6h fds a cada 2 meses · não quer o feriado 12/10 | I18: 30
A19: Kariny | B19: Fernanda Kariny | C19: 36 | D19: 36h | E19: fixa seg/ter/qui dia; NÃO quartas; 6h avulsa só de manhã | F19: não | G19: não | H19: repouso 09–12/10 (procedimento) | I19: 36
A20: Mayana | B20: Mayana Leal | C20: 36 | D20: 36h | E20: fixa ter dia, qui dia; NÃO seg/qua/sex tarde | F20: não | G20: não | I20: 36
A21: Neyde | B21: Neyde Brito | C21: 36 | D21: 36h | E21: fixa ter+qua noite + 1º/3º/4º dom noite; NÃO qui/sex/sáb noite (HMIB) | F21: não | G21: sim | H21: férias 19/10 + 15 dias | I21: 36
A22: Roberta | B22: Roberta Iglesias | C22: 36 | D22: 36h | E22: coringa | F22: não | G22: sim | I22: 36
A23: LuAlice | B23: Luciana Alice | C23: 36 | D23: 36h | E23: fixa ter+qui noite, sáb noite no fds; SÓ noturnos (+tardes CRO, código CRO) | F23: sim | G23: não | H23: NUNCA lançar banco de horas · 36h temporária, 12h/mês CRO (2 tardes) · não lançar sextas 02 e 30/10 N | I23: 36
A24: Amanda | B24: Amanda Braga | C24: 30 | D24: 30h | E24: alterna qui noite / qua dia | F24: sim | G24: sim | H24: férias até ~12/10 · NÃO escalar fds extra em outubro (fez horas a mais em set) | I24: 30
A25: Fernando | B25: Fernando Filardi | C25: 30 | D25: 30h | E25: fixo seg noite, qua+qui manhã, sáb manhã | F25: não | G25: não | H25: troca sáb 17/10 → dom 04/10 manhã; oferece sexta-noite 23/10 | I25: 30
A26: João | B26: João | C26: 30 | D26: 30h | E26: NÃO manhãs, NÃO segundas, NÃO sábados; ter/qui/sex tarde + qua noite | F26: não | G26: não | H26: extrapola fds · férias até ~06/10 | I26: 30
A27: JuCoutinho | B27: Juliana Coutinho | C27: 30 | D27: 30h | E27: fixa qua diurno, sextas manhãs; NÃO qui dia | F27: não | G27: não | H27: prefere 6h em vez de 12h | I27: 30
A28: LeLemos | B28: Leticia Lemos | C28: 30 | D28: 30h | E28: seg dia ↔ seg noite alternando | F28: 1/mês | G28: sim | H28: férias até 05/10 | I28: 30
A29: Leomara | B29: Leomara | C29: 24 | D29: 24h | E29: só seg/ter manhã, qua noite, sex dia/noite, fds; evitar 2 noturnos/semana | F29: não | G29: não | H29: 24h desde ago | I29: 24
A30: Marilia | B30: Marilia | C30: 30 | D30: 30h | E30: ter dia ↔ qua dia 15/15; sexta só manhã; NÃO segundas (Luzia) | F30: não | G30: não | H30: pediu a sexta-noite dela em out (16/10) em vez de nov | I30: 30
A31: Raylander | B31: Daniel Raylander | C31: 30 | D31: 30h | E31: NÃO seg tarde, qui manhã, sex dia (faculdade); aceita noturnos seguidos | F31: não | G31: SIM obrigatório | H31: casado com Ariadne — nunca no mesmo turno | I31: 30
A32: Ricardo | B32: Ricardo | C32: 30 | D32: 30h | E32: fixo ter noite (sai da fixa quando faz SN/fds) | F32: não | G32: sim | H32: escalar junto com Nishioka | I32: 30
A33: Rosana | B33: Rosana | C33: 30 | D33: 30h | E33: só manhãs e noites/noitinhas (mãe em quimio): SEM tardes, SEM 12h diurnas | F33: não | G33: não | H33: férias até ~12/10 | I33: 30
A34: AnaSeverino | B34: Ana Severino | C34: 24 | D34: 24h | E34: seg (M/dia/N) ou qui noite; NÃO tardes | F34: não | G34: sim | I34: 24
A35: Anna | B35: Anna Jorge | C35: 24 | D35: 24h | E35: NÃO seg manhã/noite, ter tarde, qui inteiro, sex tarde, dom noite | F35: não | G35: não | H35: habitual seg/qua tarde | I35: 24
A36: Ariadne | B36: Ariadne | C36: 24 | D36: 24h | E36: casada com Raylander — NUNCA no mesmo turno | F36: não | G36: não | H36: volta de licença 26/10, CH passa a 24h | I36: 24
A37: Beatriz | B37: Beatriz | C37: 24 | D37: 24h | E37: mora parte em SP; manda blocos de indisponibilidade | F37: sim | G37: não | I37: 24
A38: Bruna | B38: Bruna | C38: 24 | D38: 24h | E38: habitual terças (dia ou noite) | F38: não | G38: não | H38: férias a partir de 19/10 | I38: 24
A39: Constantino | B39: Fernanda Constantino | C39: 24 | D39: 24h | E39: seg noite OU ter noite, qui noite; NÃO quartas; evitar noites consecutivas | F39: não | G39: sim | H39: trabalhou 07/09 → folgar 12/10; não escalar fds 10–11 | I39: 24
A40: DebMatias | B40: Debora Matias | C40: 24 | D40: 24h | E40: ter/qua/sex dia (não toda sexta); noturno só ter noite | F40: não | G40: não | I40: 24
...

Sheet CONFIG
A1: Config · As regras como dado
A2: Mudou aqui, muda na planilha toda
A3: Em vigor · de out/26 | B3: Manhã | C3: Tarde | D3: Noite
A4: útil | B4: 14 | C4: 10 | D4: 7 | F4: Regra da Mari de 13/08/26, vale da escala de outubro em diante. Substitui 11/8/7 e 9/7/6. A 10ª da manhã de sábado é sempre a Janaina (8–13h); ela nunca faz domingo. Feriado escala como o dia da semana em que cai.
A5: sábado | B5: 10 | C5: 8 | D5: 7
A6: domingo | B6: 9 | C6: 8 | D6: 7
A8: Até set/26 · histórico | B8: Manhã | C8: Tarde | D8: Noite
A9: útil | B9: 11 | C9: 8 | D9: 7 | F9: Os meses de janeiro a setembro são medidos por ESTA regra. Cobrar deles o mínimo novo seria exigir do passado uma regra que ainda não existia.
A10: sábado | B10: 9 | C10: 7 | D10: 6
A11: domingo | B11: 9 | C11: 7 | D11: 6
A13: Tabela de códigos
A14: Letra | B14: Senior | C14: Horas | D14: Conta manhã | E14: Conta tarde | F14: Conta noite | G14: Turno
A15: M | B15: 2 | C15: 6 | D15: 1 | E15: 0 | F15: 0 | G15: manhã · 07–13h
A16: T | B16: 239 | C16: 6 | D16: 0 | E16: 1 | F16: 0 | G16: tarde · 13–19h
A17: D | B17: 40 | C17: 12 | D17: 1 | E17: 1 | F17: 0 | G17: dia 12h · 07–19h
A18: N | B18: 41 | C18: 12 | D18: 0 | E18: 0 | F18: 1 | G18: noite 12h · 19–07h
A19: NT | B19: 349 | C19: 6 | D19: 0 | E19: 0 | F19: 1 | G19: noitinha · 19–01h
A20: C | B20: 47 | C20: 10 | D20: 1 | E20: 1 | F20: 0 | G20: 10h chefia · 8–12 + 13–19h
A21: A | B21: 11 | C21: 8 | D21: 0 | E21: 0 | F21: 0 | G21: administrativo · 8h diurno
A22: J | B22: 78 | C22: 5 | D22: 1 | E22: 0 | F22: 0 | G22: 5h Janaina · 08–13h
A23: CEP | B23: 6 | C23: 4 | D23: 1 | E23: 0 | F23: 0 | G23: 4h CEP · 08–12h
A24: CP | C24: 6 | D24: 0 | E24: 0 | F24: 0 | G24: CP · cuidados paliativos · 07–13h
A25: CRO | C25: 6 | D25: 0 | E25: 0 | F25: 0 | G25: CRO · ambulatório · 13–19h
A26: M+ | C26: 6 | D26: 1 | E26: 0 | F26: 0 | G26: manhã BHP · 07–13h · banco
A27: T+ | C27: 6 | D27: 0 | E27: 1 | F27: 0 | G27: tarde BHP · 13–19h · banco
A28: D+ | C28: 12 | D28: 1 | E28: 1 | F28: 0 | G28: dia BHP · 07–19h · banco
A29: N+ | C29: 12 | D29: 0 | E29: 0 | F29: 1 | G29: noite BHP · 19–07h · banco
A30: Dm+ | B30: 239 | C30: 12 | D30: 1 | E30: 1 | F30: 0 | G30: dia · manhã é BHP · 07–19h
A31: Dt+ | B31: 2 | C31: 12 | D31: 1 | E31: 1 | F31: 0 | G31: dia · tarde é BHP · 07–19h
A32: M- | B32: 2 | C32: 0 | D32: 0 | E32: 0 | F32: 0 | G32: BHN da manhã · dispensa
A33: T- | B33: 239 | C33: 0 | D33: 0 | E33: 0 | F33: 0 | G33: BHN da tarde · dispensa
A34: D- | B34: 40 | C34: 0 | D34: 0 | E34: 0 | F34: 0 | G34: BHN do dia · dispensa
A35: N- | B35: 41 | C35: 0 | D35: 0 | E35: 0 | F35: 0 | G35: BHN da noite · dispensa
A36: Tm- | B36: 40 | C36: 6 | D36: 0 | E36: 1 | F36: 0 | G36: tarde · manhã é BHN · 13–19h
A37: Mt- | B37: 40 | C37: 6 | D37: 1 | E37: 0 | F37: 0 | G37: manhã · tarde é BHN · 07–13h
A38: FE | B38: Férias | C38: 0 | D38: 0 | E38: 0 | F38: 0 | G38: férias · —
A39: LM | B39: LM | C39: 0 | D39: 0 | E39: 0 | F39: 0 | G39: licença · —
A40: AB | C40: 0 | D40: 0 | E40: 0 | F40: 0 | G40: abono niver · —
A42: Cota de FDS em mês com férias | F42: Em mês de 5 fins de semana a demanda de fds passa da soma das cotas do grupo e zerar o excesso é aritmeticamente impossível. Outubro/26: demanda 1704h contra 1494h de cota somada — 210h que não têm de onde sair. O alvo de cada pessoa passa a ser a cota vezes o fator abaixo, para que o excesso inevitável seja dividido em proporção e não despejado em quem tem menos veto.
A43: CH semanal | B43: Férias 2 sem | C43: Férias 1 sem | D43: Sem férias | E43: Fator do mês
...

Sheet JAN
A1: Janeiro · 2026 | O1: Legenda: M manhã 7–13 · T tarde 13–19 · D dia 7–19 · N noite 19–7 · NT noitinha · C chefia 10h · J Janaina 8–13 · CEP · CP · CRO · + = BHP (a mais, no banco) · − = BHN (dispensa) · FE férias · LM licença · AB abono
F2: 29/12 | G2: 30/12 | H2: 31/12 | I2: 1 | J2: 2 | K2: 3 | L2: 4 | M2: 5 | N2: 6 | O2: 7 | P2: 8 | Q2: 9 | R2: 10 | S2: 11 | T2: 12 | U2: 13 | V2: 14 | W2: 15 | X2: 16 | Y2: 17 | Z2: 18 | AA2: 19 | AB2: 20 | AC2: 21 | AD2: 22 | AE2: 23 | AF2: 24 | AG2: 25 | AH2: 26 | AI2: 27 | AJ2: 28 | AK2: 29 | AL2: 30 | AM2: 31 | AN2: 01/02 | AT2: 29/12–04/01 | AV2: 05/01–11/01 | AX2: 12/01–18/01 | AZ2: 19/01–25/01 | BB2: 26/01–01/02
F3: seg | G3: ter | H3: qua | I3: 1ºjan | J3: sex | K3: sáb | L3: dom | M3: seg | N3: ter | O3: qua | P3: qui | Q3: sex | R3: sáb | S3: dom | T3: seg | U3: ter | V3: qua | W3: qui | X3: sex | Y3: sáb | Z3: dom | AA3: seg | AB3: ter | AC3: qua | AD3: qui | AE3: sex | AF3: sáb | AG3: dom | AH3: seg | AI3: ter | AJ3: qua | AK3: qui | AL3: sex | AM3: sáb | AN3: dom | AT3: semana civil | AV3: semana civil | AX3: semana civil | AZ3: semana civil | BB3: semana civil
A4: máscara fds | C4: 0 | D4: 0 | E4: 0 | F4: 0 | G4: 0 | H4: 0 | I4: 0 | J4: 0 | K4: 1 | L4: 1 | M4: 0 | N4: 0 | O4: 0 | P4: 0 | Q4: 0 | R4: 1 | S4: 1 | T4: 0 | U4: 0 | V4: 0 | W4: 0 | X4: 0 | Y4: 1 | Z4: 1 | AA4: 0 | AB4: 0 | AC4: 0 | AD4: 0 | AE4: 0 | AF4: 1 | AG4: 1 | AH4: 0 | AI4: 0 | AJ4: 0 | AK4: 0 | AL4: 0 | AM4: 1 | AN4: 0 | AO4: 0 | AP4: 0 | AQ4: 0 | AR4: 0 | AS4: 0
A5: máscara sexta | C5: 0 | D5: 0 | E5: 0 | F5: 0 | G5: 0 | H5: 0 | I5: 0 | J5: 1 | K5: 0 | L5: 0 | M5: 0 | N5: 0 | O5: 0 | P5: 0 | Q5: 1 | R5: 0 | S5: 0 | T5: 0 | U5: 0 | V5: 0 | W5: 0 | X5: 1 | Y5: 0 | Z5: 0 | AA5: 0 | AB5: 0 | AC5: 0 | AD5: 0 | AE5: 1 | AF5: 0 | AG5: 0 | AH5: 0 | AI5: 0 | AJ5: 0 | AK5: 0 | AL5: 1 | AM5: 0 | AN5: 0 | AO5: 0 | AP5: 0 | AQ5: 0 | AR5: 0 | AS5: 0
A6: máscara feriado | C6: 0 | D6: 0 | E6: 0 | F6: 0 | G6: 0 | H6: 0 | I6: 1 | J6: 0 | K6: 0 | L6: 0 | M6: 0 | N6: 0 | O6: 0 | P6: 0 | Q6: 0 | R6: 0 | S6: 0 | T6: 0 | U6: 0 | V6: 0 | W6: 0 | X6: 0 | Y6: 0 | Z6: 0 | AA6: 0 | AB6: 0 | AC6: 0 | AD6: 0 | AE6: 0 | AF6: 0 | AG6: 0 | AH6: 0 | AI6: 0 | AJ6: 0 | AK6: 0 | AL6: 0 | AM6: 0 | AN6: 0 | AO6: 0 | AP6: 0 | AQ6: 0 | AR6: 0 | AS6: 0
A7: Médico | B7: CH | AT7: Sem 1 | AU7: BH 1 | AV7: Sem 2 | AW7: BH 2 | AX7: Sem 3 | AY7: BH 3 | AZ7: Sem 4 | BA7: BH 4 | BB7: Sem 5 | BC7: BH 5 | BD7: Sem 6 | BE7: BH 6 | BF7: CH mês | BG7: FDS | BH7: SxN | BI7: Feriado | BJ7: Meta | BK7: Saldo | BL7: 18h⚠ | BM7: N→T | BN7: Cota FDS | BO7: FDS⚠ | BP7: Sem⚠ | BQ7: Grupo | BR7: Nº
A8: Fred | B8: 36 | J8: M | M8: M | N8: M | O8: M | P8: M | Q8: M | T8: M | U8: M | V8: M | W8: M | X8: M | AA8: M | AB8: M | AC8: M | AD8: M | AE8: M | AN8: =IFERROR(INDEX(FEV!I$8:I$73,MATCH($A8,FEV!$A$8:$A$73,0))&"","") | AT8: =SUMPRODUCT(($F8:$L8="M")*6+($F8:$L8="T")*6+($F8:$L8="D")*12+($F8:$L8="N")*12+($F8:$L8="NT")*6+($F8:$L8="C")*10+($F8:$L8="A")*8+($F8:$L8="J")*5+($F8:$L8="CEP")*4+($F8:$L8="CP")*6+($F8:$L8="CRO")*6+($F8:$L8="M+")*6+($F8:$L8="T+")*6+($F8:$L8="D+")*12+($F8:$L8="N+")*12+($F8:$L8="Dm+")*12+($F8:$L8="Dt+")*12+($F8:$L8="Tm-")*6+($F8:$L8="Mt-")*6) | AU8: =AT8-MAX(0,IFERROR(INDEX(CADASTRO!$I$4:$I$80,MATCH($A8,CADASTRO!$A$4:$A$80,0)),$B8)-CONFIG!$B$50*(COUNTIF($F8:$L8,"AB")+COUNTIF($F8:$L8,"FE")+COUNTIF($F8:$L8,"LM"))) | AV8: =SUMPRODUCT(($M8:$S8="M")*6+($M8:$S8="T")*6+($M8:$S8="D")*12+($M8:$S8="N")*12+($M8:$S8="NT")*6+($M8:$S8="C")*10+($M8:$S8="A")*8+($M8:$S8="J")*5+($M8:$S8="CEP")*4+($M8:$S8="CP")*6+($M8:$S8="CRO")*6+($M8:$S8="M+")*6+($M8:$S8="T+")*6+($M8:$S8="D+")*12+($M8:$S8="N+")*12+($M8:$S8="Dm+")*12+($M8:$S8="Dt+")*12+($M8:$S8="Tm-")*6+($M8:$S8="Mt-")*6) | AW8: =AV8-MAX(0,IFERROR(INDEX(CADASTRO!$I$4:$I$80,MATCH($A8,CADASTRO!$A$4:$A$80,0)),$B8)-CONFIG!$B$50*(COUNTIF($M8:$S8,"AB")+COUNTIF($M8:$S8,"FE")+COUNTIF($M8:$S8,"LM"))) | AX8: =SUMPRODUCT(($T8:$Z8="M")*6+($T8:$Z8="T")*6+($T8:$Z8="D")*12+($T8:$Z8="N")*12+($T8:$Z8="NT")*6+($T8:$Z8="C")*10+($T8:$Z8="A")*8+($T8:$Z8="J")*5+($T8:$Z8="CEP")*4+($T8:$Z8="CP")*6+($T8:$Z8="CRO")*6+($T8:$Z8="M+")*6+($T8:$Z8="T+")*6+($T8:$Z8="D+")*12+($T8:$Z8="N+")*12+($T8:$Z8="Dm+")*12+($T8:$Z8="Dt+")*12+($T8:$Z8="Tm-")*6+($T8:$Z8="Mt-")*6) | AY8: =AX8-MAX(0,IFERROR(INDEX(CADASTRO!$I$4:$I$80,MATCH($A8,CADASTRO!$A$4:$A$80,0)),$B8)-CONFIG!$B$50*(COUNTIF($T8:$Z8,"AB")+COUNTIF($T8:$Z8,"FE")+COUNTIF($T8:$Z8,"LM"))) | AZ8: =SUMPRODUCT(($AA8:$AG8="M")*6+($AA8:$AG8="T")*6+($AA8:$AG8="D")*12+($AA8:$AG8="N")*12+($AA8:$AG8="NT")*6+($AA8:$AG8="C")*10+($AA8:$AG8="A")*8+($AA8:$AG8="J")*5+($AA8:$AG8="CEP")*4+($AA8:$AG8="CP")*6+($AA8:$AG8="CRO")*6+($AA8:$AG8="M+")*6+($AA8:$AG8="T+")*6+($AA8:$AG8="D+")*12+($AA8:$AG8="N+")*12+($AA8:$AG8="Dm+")*12+($AA8:$AG8="Dt+")*12+($AA8:$AG8="Tm-")*6+($AA8:$AG8="Mt-")*6) | BA8: =AZ8-MAX(0,IFERROR(INDEX(CADASTRO!$I$4:$I$80,MATCH($A8,CADASTRO!$A$4:$A$80,0)),$B8)-CONFIG!$B$50*(COUNTIF($AA8:$AG8,"AB")+COUNTIF($AA8:$AG8,"FE")+COUNTIF($AA8:$AG8,"LM"))) | BB8: =SUMPRODUCT(($AH8:$AM8="M")*6+($AH8:$AM8="T")*6+($AH8:$AM8="D")*12+($AH8:$AM8="N")*12+($AH8:$AM8="NT")*6+($AH8:$AM8="C")*10+($AH8:$AM8="A")*8+($AH8:$AM8="J")*5+($AH8:$AM8="CEP")*4+($AH8:$AM8="CP")*6+($AH8:$AM8="CRO")*6+($AH8:$AM8="M+")*6+($AH8:$AM8="T+")*6+($AH8:$AM8="D+")*12+($AH8:$AM8="N+")*12+($AH8:$AM8="Dm+")*12+($AH8:$AM8="Dt+")*12+($AH8:$AM8="Tm-")*6+($AH8:$AM8="Mt-")*6)+SUMPRODUCT(($AN8:$AN8="M")*6+($AN8:$AN8="T")*6+($AN8:$AN8="D")*12+($AN8:$AN8="N")*12+($AN8:$AN8="NT")*6+($AN8:$AN8="C")*10+($AN8:$AN8="A")*8+($AN8:$AN8="J")*5+($AN8:$AN8="CEP")*4+($AN8:$AN8="CP")*6+($AN8:$AN8="CRO")*6+($AN8:$AN8="M+")*6+($AN8:$AN8="T+")*6+($AN8:$AN8="D+")*12+($AN8:$AN8="N+")*12+($AN8:$AN8="Dm+")*12+($AN8:$AN8="Dt+")*12+($AN8:$AN8="Tm-")*6+($AN8:$AN8="Mt-")*6) | BC8: =BB8-MAX(0,IFERROR(INDEX(CADASTRO!$I$4:$I$80,MATCH($A8,CADASTRO!$A$4:$A$80,0)),$B8)-CONFIG!$B$50*(COUNTIF($AH8:$AM8,"AB")+COUNTIF($AH8:$AM8,"FE")+COUNTIF($AH8:$AM8,"LM")+COUNTIF($AN8:$AN8,"AB")+COUNTIF($AN8:$AN8,"FE")+COUNTIF($AN8:$AN8,"LM"))) | BF8: =SUMPRODUCT(($I8:$AM8="M")*6+($I8:$AM8="T")*6+($I8:$AM8="D")*12+($I8:$AM8="N")*12+($I8:$AM8="NT")*6+($I8:$AM8="C")*10+($I8:$AM8="A")*8+($I8:$AM8="J")*5+($I8:$AM8="CEP")*4+($I8:$AM8="CP")*6+($I8:$AM8="CRO")*6+($I8:$AM8="M+")*6+($I8:$AM8="T+")*6+($I8:$AM8="D+")*12+($I8:$AM8="N+")*12+($I8:$AM8="Dm+")*12+($I8:$AM8="Dt+")*12+($I8:$AM8="Tm-")*6+($I8:$AM8="Mt-")*6) | BG8: =SUMPRODUCT($I$4:$AM$4,($I8:$AM8="M")*6+($I8:$AM8="T")*6+($I8:$AM8="D")*12+($I8:$AM8="N")*12+($I8:$AM8="NT")*6+($I8:$AM8="C")*10+($I8:$AM8="A")*8+($I8:$AM8="J")*5+($I8:$AM8="CEP")*4+($I8:$AM8="CP")*6+($I8:$AM8="CRO")*6+($I8:$AM8="M+")*6+($I8:$AM8="T+")*6+($I8:$AM8="D+")*12+($I8:$AM8="N+")*12+($I8:$AM8="Dm+")*12+($I8:$AM8="Dt+")*12+($I8:$AM8="Tm-")*6+($I8:$AM8="Mt-")*6) | BH8: =SUMPRODUCT($I$5:$AM$5,(($I8:$AM8="N")+($I8:$AM8="N+"))) | BI8: =SUMPRODUCT($I$6:$AM$6,($I8:$AM8="M")*6+($I8:$AM8="T")*6+($I8:$AM8="D")*12+($I8:$AM8="N")*12+($I8:$AM8="NT")*6+($I8:$AM8="C")*10+($I8:$AM8="A")*8+($I8:$AM8="J")*5+($I8:$AM8="CEP")*4+($I8:$AM8="CP")*6+($I8:$AM8="CRO")*6+($I8:$AM8="M+")*6+($I8:$AM8="T+")*6+($I8:$AM8="D+")*12+($I8:$AM8="N+")*12+($I8:$AM8="Dm+")*12+($I8:$AM8="Dt+")*12+($I8:$AM8="Tm-")*6+($I8:$AM8="Mt-")*6) | BJ8: =ROUND(B8*4.43,0) | BK8: =BF8-BJ8 | BL8: =SUMPRODUCT((($C8:$AL8="N")+($C8:$AL8="N+"))*(($D8:$AM8="M")+($D8:$AM8="D")+($D8:$AM8="C")+($D8:$AM8="CEP")+($D8:$AM8="M+")+($D8:$AM8="D+")+($D8:$AM8="Dm+")+($D8:$AM8="Dt+")+($D8:$AM8="Mt-"))) | BM8: =SUMPRODUCT((($C8:$AL8="N")+($C8:$AL8="N+"))*(($D8:$AM8="T")+($D8:$AM8="T+")+($D8:$AM8="Tm-"))) | BN8: =IFERROR(INDEX(CONFIG!$B$44:$D$46,MATCH($B8,CONFIG!$A$44:$A$46,0),IF(COUNTIF($I8:$AM8,"FE")>=10,1,IF(COUNTIF($I8:$AM8,"FE")>=1,2,3))),"") | BO8: =IF(BN8="","",MAX(0,BG8-BN8*CONFIG!$E$44)) | BP8: =MAX(AT8,AV8,AX8,AZ8,BB8,BD8) | BQ8: 1 · coordenação | BR8: 7
A9: Milena | B9: 36 | J9: M | M9: M | N9: M | O9: M | P9: M | Q9: M | T9: M | U9: M | V9: M | W9: M | X9: M | AA9: M | AB9: M | AC9: M | AD9: M | AE9: M | AH9: M | AI9: M | AJ9: M | AK9: M | AL9: M | AN9: =IFERROR(INDEX(FEV!I$8:I$73,MATCH($A9,FEV!$A$8:$A$73,0))&"","") | AT9: =SUMPRODUCT(($F9:$L9="M")*6+($F9:$L9="T")*6+($F9:$L9="D")*12+($F9:$L9="N")*12+($F9:$L9="NT")*6+($F9:$L9="C")*10+($F9:$L9="A")*8+($F9:$L9="J")*5+($F9:$L9="CEP")*4+($F9:$L9="CP")*6+($F9:$L9="CRO")*6+($F9:$L9="M+")*6+($F9:$L9="T+")*6+($F9:$L9="D+")*12+($F9:$L9="N+")*12+($F9:$L9="Dm+")*12+($F9:$L9="Dt+")*12+($F9:$L9="Tm-")*6+($F9:$L9="Mt-")*6) | AU9: =AT9-MAX(0,IFERROR(INDEX(CADASTRO!$I$4:$I$80,MATCH($A9,CADASTRO!$A$4:$A$80,0)),$B9)-CONFIG!$B$50*(COUNTIF($F9:$L9,"AB")+COUNTIF($F9:$L9,"FE")+COUNTIF($F9:$L9,"LM"))) | AV9: =SUMPRODUCT(($M9:$S9="M")*6+($M9:$S9="T")*6+($M9:$S9="D")*12+($M9:$S9="N")*12+($M9:$S9="NT")*6+($M9:$S9="C")*10+($M9:$S9="A")*8+($M9:$S9="J")*5+($M9:$S9="CEP")*4+($M9:$S9="CP")*6+($M9:$S9="CRO")*6+($M9:$S9="M+")*6+($M9:$S9="T+")*6+($M9:$S9="D+")*12+($M9:$S9="N+")*12+($M9:$S9="Dm+")*12+($M9:$S9="Dt+")*12+($M9:$S9="Tm-")*6+($M9:$S9="Mt-")*6) | AW9: =AV9-MAX(0,IFERROR(INDEX(CADASTRO!$I$4:$I$80,MATCH($A9,CADASTRO!$A$4:$A$80,0)),$B9)-CONFIG!$B$50*(COUNTIF($M9:$S9,"AB")+COUNTIF($M9:$S9,"FE")+COUNTIF($M9:$S9,"LM"))) | AX9: =SUMPRODUCT(($T9:$Z9="M")*6+($T9:$Z9="T")*6+($T9:$Z9="D")*12+($T9:$Z9="N")*12+($T9:$Z9="NT")*6+($T9:$Z9="C")*10+($T9:$Z9="A")*8+($T9:$Z9="J")*5+($T9:$Z9="CEP")*4+($T9:$Z9="CP")*6+($T9:$Z9="CRO")*6+($T9:$Z9="M+")*6+($T9:$Z9="T+")*6+($T9:$Z9="D+")*12+($T9:$Z9="N+")*12+($T9:$Z9="Dm+")*12+($T9:$Z9="Dt+")*12+($T9:$Z9="Tm-")*6+($T9:$Z9="Mt-")*6) | AY9: =AX9-MAX(0,IFERROR(INDEX(CADASTRO!$I$4:$I$80,MATCH($A9,CADASTRO!$A$4:$A$80,0)),$B9)-CONFIG!$B$50*(COUNTIF($T9:$Z9,"AB")+COUNTIF($T9:$Z9,"FE")+COUNTIF($T9:$Z9,"LM"))) | AZ9: =SUMPRODUCT(($AA9:$AG9="M")*6+($AA9:$AG9="T")*6+($AA9:$AG9="D")*12+($AA9:$AG9="N")*12+($AA9:$AG9="NT")*6+($AA9:$AG9="C")*10+($AA9:$AG9="A")*8+($AA9:$AG9="J")*5+($AA9:$AG9="CEP")*4+($AA9:$AG9="CP")*6+($AA9:$AG9="CRO")*6+($AA9:$AG9="M+")*6+($AA9:$AG9="T+")*6+($AA9:$AG9="D+")*12+($AA9:$AG9="N+")*12+($AA9:$AG9="Dm+")*12+($AA9:$AG9="Dt+")*12+($AA9:$AG9="Tm-")*6+($AA9:$AG9="Mt-")*6) | BA9: =AZ9-MAX(0,IFERROR(INDEX(CADASTRO!$I$4:$I$80,MATCH($A9,CADASTRO!$A$4:$A$80,0)),$B9)-CONFIG!$B$50*(COUNTIF($AA9:$AG9,"AB")+COUNTIF($AA9:$AG9,"FE")+COUNTIF($AA9:$AG9,"LM"))) | BB9: =SUMPRODUCT(($AH9:$AM9="M")*6+($AH9:$AM9="T")*6+($AH9:$AM9="D")*12+($AH9:$AM9="N")*12+($AH9:$AM9="NT")*6+($AH9:$AM9="C")*10+($AH9:$AM9="A")*8+($AH9:$AM9="J")*5+($AH9:$AM9="CEP")*4+($AH9:$AM9="CP")*6+($AH9:$AM9="CRO")*6+($AH9:$AM9="M+")*6+($AH9:$AM9="T+")*6+($AH9:$AM9="D+")*12+($AH9:$AM9="N+")*12+($AH9:$AM9="Dm+")*12+($AH9:$AM9="Dt+")*12+($AH9:$AM9="Tm-")*6+($AH9:$AM9="Mt-")*6)+SUMPRODUCT(($AN9:$AN9="M")*6+($AN9:$AN9="T")*6+($AN9:$AN9="D")*12+($AN9:$AN9="N")*12+($AN9:$AN9="NT")*6+($AN9:$AN9="C")*10+($AN9:$AN9="A")*8+($AN9:$AN9="J")*5+($AN9:$AN9="CEP")*4+($AN9:$AN9="CP")*6+($AN9:$AN9="CRO")*6+($AN9:$AN9="M+")*6+($AN9:$AN9="T+")*6+($AN9:$AN9="D+")*12+($AN9:$AN9="N+")*12+($AN9:$AN9="Dm+")*12+($AN9:$AN9="Dt+")*12+($AN9:$AN9="Tm-")*6+($AN9:$AN9="Mt-")*6) | BC9: =BB9-MAX(0,IFERROR(INDEX(CADASTRO!$I$4:$I$80,MATCH($A9,CADASTRO!$A$4:$A$80,0)),$B9)-CONFIG!$B$50*(COUNTIF($AH9:$AM9,"AB")+COUNTIF($AH9:$AM9,"FE")+COUNTIF($AH9:$AM9,"LM")+COUNTIF($AN9:$AN9,"AB")+COUNTIF($AN9:$AN9,"FE")+COUNTIF($AN9:$AN9,"LM"))) | BF9: =SUMPRODUCT(($I9:$AM9="M")*6+($I9:$AM9="T")*6+($I9:$AM9="D")*12+($I9:$AM9="N")*12+($I9:$AM9="NT")*6+($I9:$AM9="C")*10+($I9:$AM9="A")*8+($I9:$AM9="J")*5+($I9:$AM9="CEP")*4+($I9:$AM9="CP")*6+($I9:$AM9="CRO")*6+($I9:$AM9="M+")*6+($I9:$AM9="T+")*6+($I9:$AM9="D+")*12+($I9:$AM9="N+")*12+($I9:$AM9="Dm+")*12+($I9:$AM9="Dt+")*12+($I9:$AM9="Tm-")*6+($I9:$AM9="Mt-")*6) | BG9: =SUMPRODUCT($I$4:$AM$4,($I9:$AM9="M")*6+($I9:$AM9="T")*6+($I9:$AM9="D")*12+($I9:$AM9="N")*12+($I9:$AM9="NT")*6+($I9:$AM9="C")*10+($I9:$AM9="A")*8+($I9:$AM9="J")*5+($I9:$AM9="CEP")*4+($I9:$AM9="CP")*6+($I9:$AM9="CRO")*6+($I9:$AM9="M+")*6+($I9:$AM9="T+")*6+($I9:$AM9="D+")*12+($I9:$AM9="N+")*12+($I9:$AM9="Dm+")*12+($I9:$AM9="Dt+")*12+($I9:$AM9="Tm-")*6+($I9:$AM9="Mt-")*6) | BH9: =SUMPRODUCT($I$5:$AM$5,(($I9:$AM9="N")+($I9:$AM9="N+"))) | BI9: =SUMPRODUCT($I$6:$AM$6,($I9:$AM9="M")*6+($I9:$AM9="T")*6+($I9:$AM9="D")*12+($I9:$AM9="N")*12+($I9:$AM9="NT")*6+($I9:$AM9="C")*10+($I9:$AM9="A")*8+($I9:$AM9="J")*5+($I9:$AM9="CEP")*4+($I9:$AM9="CP")*6+($I9:$AM9="CRO")*6+($I9:$AM9="M+")*6+($I9:$AM9="T+")*6+($I9:$AM9="D+")*12+($I9:$AM9="N+")*12+($I9:$AM9="Dm+")*12+($I9:$AM9="Dt+")*12+($I9:$AM9="Tm-")*6+($I9:$AM9="Mt-")*6) | BJ9: =ROUND(B9*4.43,0) | BK9: =BF9-BJ9 | BL9: =SUMPRODUCT((($C9:$AL9="N")+($C9:$AL9="N+"))*(($D9:$AM9="M")+($D9:$AM9="D")+($D9:$AM9="C")+($D9:$AM9="CEP")+($D9:$AM9="M+")+($D9:$AM9="D+")+($D9:$AM9="Dm+")+($D9:$AM9="Dt+")+($D9:$AM9="Mt-"))) | BM9: =SUMPRODUCT((($C9:$AL9="N")+($C9:$AL9="N+"))*(($D9:$AM9="T")+($D9:$AM9="T+")+($D9:$AM9="Tm-"))) | BN9: =IFERROR(INDEX(CONFIG!$B$44:$D$46,MATCH($B9,CONFIG!$A$44:$A$46,0),IF(COUNTIF($I9:$AM9,"FE")>=10,1,IF(COUNTIF($I9:$AM9,"FE")>=1,2,3))),"") | BO9: =IF(BN9="","",MAX(0,BG9-BN9*CONFIG!$E$44)) | BP9: =MAX(AT9,AV9,AX9,AZ9,BB9,BD9) | BQ9: 1 · coordenação | BR9: 7
A10: Pabdo | B10: 36 | AN10: =IFERROR(INDEX(FEV!I$8:I$73,MATCH($A10,FEV!$A$8:$A$73,0))&"","") | AT10: =SUMPRODUCT(($F10:$L10="M")*6+($F10:$L10="T")*6+($F10:$L10="D")*12+($F10:$L10="N")*12+($F10:$L10="NT")*6+($F10:$L10="C")*10+($F10:$L10="A")*8+($F10:$L10="J")*5+($F10:$L10="CEP")*4+($F10:$L10="CP")*6+($F10:$L10="CRO")*6+($F10:$L10="M+")*6+($F10:$L10="T+")*6+($F10:$L10="D+")*12+($F10:$L10="N+")*12+($F10:$L10="Dm+")*12+($F10:$L10="Dt+")*12+($F10:$L10="Tm-")*6+($F10:$L10="Mt-")*6) | AU10: =AT10-MAX(0,IFERROR(INDEX(CADASTRO!$I$4:$I$80,MATCH($A10,CADASTRO!$A$4:$A$80,0)),$B10)-CONFIG!$B$50*(COUNTIF($F10:$L10,"AB")+COUNTIF($F10:$L10,"FE")+COUNTIF($F10:$L10,"LM"))) | AV10: =SUMPRODUCT(($M10:$S10="M")*6+($M10:$S10="T")*6+($M10:$S10="D")*12+($M10:$S10="N")*12+($M10:$S10="NT")*6+($M10:$S10="C")*10+($M10:$S10="A")*8+($M10:$S10="J")*5+($M10:$S10="CEP")*4+($M10:$S10="CP")*6+($M10:$S10="CRO")*6+($M10:$S10="M+")*6+($M10:$S10="T+")*6+($M10:$S10="D+")*12+($M10:$S10="N+")*12+($M10:$S10="Dm+")*12+($M10:$S10="Dt+")*12+($M10:$S10="Tm-")*6+($M10:$S10="Mt-")*6) | AW10: =AV10-MAX(0,IFERROR(INDEX(CADASTRO!$I$4:$I$80,MATCH($A10,CADASTRO!$A$4:$A$80,0)),$B10)-CONFIG!$B$50*(COUNTIF($M10:$S10,"AB")+COUNTIF($M10:$S10,"FE")+COUNTIF($M10:$S10,"LM"))) | AX10: =SUMPRODUCT(($T10:$Z10="M")*6+($T10:$Z10="T")*6+($T10:$Z10="D")*12+($T10:$Z10="N")*12+($T10:$Z10="NT")*6+($T10:$Z10="C")*10+($T10:$Z10="A")*8+($T10:$Z10="J")*5+($T10:$Z10="CEP")*4+($T10:$Z10="CP")*6+($T10:$Z10="CRO")*6+($T10:$Z10="M+")*6+($T10:$Z10="T+")*6+($T10:$Z10="D+")*12+($T10:$Z10="N+")*12+($T10:$Z10="Dm+")*12+($T10:$Z10="Dt+")*12+($T10:$Z10="Tm-")*6+($T10:$Z10="Mt-")*6) | AY10: =AX10-MAX(0,IFERROR(INDEX(CADASTRO!$I$4:$I$80,MATCH($A10,CADASTRO!$A$4:$A$80,0)),$B10)-CONFIG!$B$50*(COUNTIF($T10:$Z10,"AB")+COUNTIF($T10:$Z10,"FE")+COUNTIF($T10:$Z10,"LM"))) | AZ10: =SUMPRODUCT(($AA10:$AG10="M")*6+($AA10:$AG10="T")*6+($AA10:$AG10="D")*12+($AA10:$AG10="N")*12+($AA10:$AG10="NT")*6+($AA10:$AG10="C")*10+($AA10:$AG10="A")*8+($AA10:$AG10="J")*5+($AA10:$AG10="CEP")*4+($AA10:$AG10="CP")*6+($AA10:$AG10="CRO")*6+($AA10:$AG10="M+")*6+($AA10:$AG10="T+")*6+($AA10:$AG10="D+")*12+($AA10:$AG10="N+")*12+($AA10:$AG10="Dm+")*12+($AA10:$AG10="Dt+")*12+($AA10:$AG10="Tm-")*6+($AA10:$AG10="Mt-")*6) | BA10: =AZ10-MAX(0,IFERROR(INDEX(CADASTRO!$I$4:$I$80,MATCH($A10,CADASTRO!$A$4:$A$80,0)),$B10)-CONFIG!$B$50*(COUNTIF($AA10:$AG10,"AB")+COUNTIF($AA10:$AG10,"FE")+COUNTIF($AA10:$AG10,"LM"))) | BB10: =SUMPRODUCT(($AH10:$AM10="M")*6+($AH10:$AM10="T")*6+($AH10:$AM10="D")*12+($AH10:$AM10="N")*12+($AH10:$AM10="NT")*6+($AH10:$AM10="C")*10+($AH10:$AM10="A")*8+($AH10:$AM10="J")*5+($AH10:$AM10="CEP")*4+($AH10:$AM10="CP")*6+($AH10:$AM10="CRO")*6+($AH10:$AM10="M+")*6+($AH10:$AM10="T+")*6+($AH10:$AM10="D+")*12+($AH10:$AM10="N+")*12+($AH10:$AM10="Dm+")*12+($AH10:$AM10="Dt+")*12+($AH10:$AM10="Tm-")*6+($AH10:$AM10="Mt-")*6)+SUMPRODUCT(($AN10:$AN10="M")*6+($AN10:$AN10="T")*6+($AN10:$AN10="D")*12+($AN10:$AN10="N")*12+($AN10:$AN10="NT")*6+($AN10:$AN10="C")*10+($AN10:$AN10="A")*8+($AN10:$AN10="J")*5+($AN10:$AN10="CEP")*4+($AN10:$AN10="CP")*6+($AN10:$AN10="CRO")*6+($AN10:$AN10="M+")*6+($AN10:$AN10="T+")*6+($AN10:$AN10="D+")*12+($AN10:$AN10="N+")*12+($AN10:$AN10="Dm+")*12+($AN10:$AN10="Dt+")*12+($AN10:$AN10="Tm-")*6+($AN10:$AN10="Mt-")*6) | BC10: =BB10-MAX(0,IFERROR(INDEX(CADASTRO!$I$4:$I$80,MATCH($A10,CADASTRO!$A$4:$A$80,0)),$B10)-CONFIG!$B$50*(COUNTIF($AH10:$AM10,"AB")+COUNTIF($AH10:$AM10,"FE")+COUNTIF($AH10:$AM10,"LM")+COUNTIF($AN10:$AN10,"AB")+COUNTIF($AN10:$AN10,"FE")+COUNTIF($AN10:$AN10,"LM"))) | BF10: =SUMPRODUCT(($I10:$AM10="M")*6+($I10:$AM10="T")*6+($I10:$AM10="D")*12+($I10:$AM10="N")*12+($I10:$AM10="NT")*6+($I10:$AM10="C")*10+($I10:$AM10="A")*8+($I10:$AM10="J")*5+($I10:$AM10="CEP")*4+($I10:$AM10="CP")*6+($I10:$AM10="CRO")*6+($I10:$AM10="M+")*6+($I10:$AM10="T+")*6+($I10:$AM10="D+")*12+($I10:$AM10="N+")*12+($I10:$AM10="Dm+")*12+($I10:$AM10="Dt+")*12+($I10:$AM10="Tm-")*6+($I10:$AM10="Mt-")*6) | BG10: =SUMPRODUCT($I$4:$AM$4,($I10:$AM10="M")*6+($I10:$AM10="T")*6+($I10:$AM10="D")*12+($I10:$AM10="N")*12+($I10:$AM10="NT")*6+($I10:$AM10="C")*10+($I10:$AM10="A")*8+($I10:$AM10="J")*5+($I10:$AM10="CEP")*4+($I10:$AM10="CP")*6+($I10:$AM10="CRO")*6+($I10:$AM10="M+")*6+($I10:$AM10="T+")*6+($I10:$AM10="D+")*12+($I10:$AM10="N+")*12+($I10:$AM10="Dm+")*12+($I10:$AM10="Dt+")*12+($I10:$AM10="Tm-")*6+($I10:$AM10="Mt-")*6) | BH10: =SUMPRODUCT($I$5:$AM$5,(($I10:$AM10="N")+($I10:$AM10="N+"))) | BI10: =SUMPRODUCT($I$6:$AM$6,($I10:$AM10="M")*6+($I10:$AM10="T")*6+($I10:$AM10="D")*12+($I10:$AM10="N")*12+($I10:$AM10="NT")*6+($I10:$AM10="C")*10+($I10:$AM10="A")*8+($I10:$AM10="J")*5+($I10:$AM10="CEP")*4+($I10:$AM10="CP")*6+($I10:$AM10="CRO")*6+($I10:$AM10="M+")*6+($I10:$AM10="T+")*6+($I10:$AM10="D+")*12+($I10:$AM10="N+")*12+($I10:$AM10="Dm+")*12+($I10:$AM10="Dt+")*12+($I10:$AM10="Tm-")*6+($I10:$AM10="Mt-")*6) | BJ10: =ROUND(B10*4.43,0) | BK10: =BF10-BJ10 | BL10: =SUMPRODUCT((($C10:$AL10="N")+($C10:$AL10="N+"))*(($D10:$AM10="M")+($D10:$AM10="D")+($D10:$AM10="C")+($D10:$AM10="CEP")+($D10:$AM10="M+")+($D10:$AM10="D+")+($D10:$AM10="Dm+")+($D10:$AM10="Dt+")+($D10:$AM10="Mt-"))) | BM10: =SUMPRODUCT((($C10:$AL10="N")+($C10:$AL10="N+"))*(($D10:$AM10="T")+($D10:$AM10="T+")+($D10:$AM10="Tm-"))) | BN10: =IFERROR(INDEX(CONFIG!$B$44:$D$46,MATCH($B10,CONFIG!$A$44:$A$46,0),IF(COUNTIF($I10:$AM10,"FE")>=10,1,IF(COUNTIF($I10:$AM10,"FE")>=1,2,3))),"") | BO10: =IF(BN10="","",MAX(0,BG10-BN10*CONFIG!$E$44)) | BP10: =MAX(AT10,AV10,AX10,AZ10,BB10,BD10) | BQ10: 2 · rotina | BR10: 7
A11: MSalomão | B11: 40 | J11: Dm+ | L11: M | M11: M | N11: D | O11: M | P11: M | Q11: M | T11: M | U11: M | V11: M | W11: M | X11: M | Z11: N | AA11: M | AB11: D | AC11: M | AD11: D | AE11: M | AH11: M | AI11: M | AJ11: M | AK11: M | AL11: M | AM11: N | AN11: =IFERROR(INDEX(FEV!I$8:I$73,MATCH($A11,FEV!$A$8:$A$73,0))&"","") | AT11: =SUMPRODUCT(($F11:$L11="M")*6+($F11:$L11="T")*6+($F11:$L11="D")*12+($F11:$L11="N")*12+($F11:$L11="NT")*6+($F11:$L11="C")*10+($F11:$L11="A")*8+($F11:$L11="J")*5+($F11:$L11="CEP")*4+($F11:$L11="CP")*6+($F11:$L11="CRO")*6+($F11:$L11="M+")*6+($F11:$L11="T+")*6+($F11:$L11="D+")*12+($F11:$L11="N+")*12+($F11:$L11="Dm+")*12+($F11:$L11="Dt+")*12+($F11:$L11="Tm-")*6+($F11:$L11="Mt-")*6) | AU11: =AT11-MAX(0,IFERROR(INDEX(CADASTRO!$I$4:$I$80,MATCH($A11,CADASTRO!$A$4:$A$80,0)),$B11)-CONFIG!$B$50*(COUNTIF($F11:$L11,"AB")+COUNTIF($F11:$L11,"FE")+COUNTIF($F11:$L11,"LM"))) | AV11: =SUMPRODUCT(($M11:$S11="M")*6+($M11:$S11="T")*6+($M11:$S11="D")*12+($M11:$S11="N")*12+($M11:$S11="NT")*6+($M11:$S11="C")*10+($M11:$S11="A")*8+($M11:$S11="J")*5+($M11:$S11="CEP")*4+($M11:$S11="CP")*6+($M11:$S11="CRO")*6+($M11:$S11="M+")*6+($M11:$S11="T+")*6+($M11:$S11="D+")*12+($M11:$S11="N+")*12+($M11:$S11="Dm+")*12+($M11:$S11="Dt+")*12+($M11:$S11="Tm-")*6+($M11:$S11="Mt-")*6) | AW11: =AV11-MAX(0,IFERROR(INDEX(CADASTRO!$I$4:$I$80,MATCH($A11,CADASTRO!$A$4:$A$80,0)),$B11)-CONFIG!$B$50*(COUNTIF($M11:$S11,"AB")+COUNTIF($M11:$S11,"FE")+COUNTIF($M11:$S11,"LM"))) | AX11: =SUMPRODUCT(($T11:$Z11="M")*6+($T11:$Z11="T")*6+($T11:$Z11="D")*12+($T11:$Z11="N")*12+($T11:$Z11="NT")*6+($T11:$Z11="C")*10+($T11:$Z11="A")*8+($T11:$Z11="J")*5+($T11:$Z11="CEP")*4+($T11:$Z11="CP")*6+($T11:$Z11="CRO")*6+($T11:$Z11="M+")*6+($T11:$Z11="T+")*6+($T11:$Z11="D+")*12+($T11:$Z11="N+")*12+($T11:$Z11="Dm+")*12+($T11:$Z11="Dt+")*12+($T11:$Z11="Tm-")*6+($T11:$Z11="Mt-")*6) | AY11: =AX11-MAX(0,IFERROR(INDEX(CADASTRO!$I$4:$I$80,MATCH($A11,CADASTRO!$A$4:$A$80,0)),$B11)-CONFIG!$B$50*(COUNTIF($T11:$Z11,"AB")+COUNTIF($T11:$Z11,"FE")+COUNTIF($T11:$Z11,"LM"))) | AZ11: =SUMPRODUCT(($AA11:$AG11="M")*6+($AA11:$AG11="T")*6+($AA11:$AG11="D")*12+($AA11:$AG11="N")*12+($AA11:$AG11="NT")*6+($AA11:$AG11="C")*10+($AA11:$AG11="A")*8+($AA11:$AG11="J")*5+($AA11:$AG11="CEP")*4+($AA11:$AG11="CP")*6+($AA11:$AG11="CRO")*6+($AA11:$AG11="M+")*6+($AA11:$AG11="T+")*6+($AA11:$AG11="D+")*12+($AA11:$AG11="N+")*12+($AA11:$AG11="Dm+")*12+($AA11:$AG11="Dt+")*12+($AA11:$AG11="Tm-")*6+($AA11:$AG11="Mt-")*6) | BA11: =AZ11-MAX(0,IFERROR(INDEX(CADASTRO!$I$4:$I$80,MATCH($A11,CADASTRO!$A$4:$A$80,0)),$B11)-CONFIG!$B$50*(COUNTIF($AA11:$AG11,"AB")+COUNTIF($AA11:$AG11,"FE")+COUNTIF($AA11:$AG11,"LM"))) | BB11: =SUMPRODUCT(($AH11:$AM11="M")*6+($AH11:$AM11="T")*6+($AH11:$AM11="D")*12+($AH11:$AM11="N")*12+($AH11:$AM11="NT")*6+($AH11:$AM11="C")*10+($AH11:$AM11="A")*8+($AH11:$AM11="J")*5+($AH11:$AM11="CEP")*4+($AH11:$AM11="CP")*6+($AH11:$AM11="CRO")*6+($AH11:$AM11="M+")*6+($AH11:$AM11="T+")*6+($AH11:$AM11="D+")*12+($AH11:$AM11="N+")*12+($AH11:$AM11="Dm+")*12+($AH11:$AM11="Dt+")*12+($AH11:$AM11="Tm-")*6+($AH11:$AM11="Mt-")*6)+SUMPRODUCT(($AN11:$AN11="M")*6+($AN11:$AN11="T")*6+($AN11:$AN11="D")*12+($AN11:$AN11="N")*12+($AN11:$AN11="NT")*6+($AN11:$AN11="C")*10+($AN11:$AN11="A")*8+($AN11:$AN11="J")*5+($AN11:$AN11="CEP")*4+($AN11:$AN11="CP")*6+($AN11:$AN11="CRO")*6+($AN11:$AN11="M+")*6+($AN11:$AN11="T+")*6+($AN11:$AN11="D+")*12+($AN11:$AN11="N+")*12+($AN11:$AN11="Dm+")*12+($AN11:$AN11="Dt+")*12+($AN11:$AN11="Tm-")*6+($AN11:$AN11="Mt-")*6) | BC11: =BB11-MAX(0,IFERROR(INDEX(CADASTRO!$I$4:$I$80,MATCH($A11,CADASTRO!$A$4:$A$80,0)),$B11)-CONFIG!$B$50*(COUNTIF($AH11:$AM11,"AB")+COUNTIF($AH11:$AM11,"FE")+COUNTIF($AH11:$AM11,"LM")+COUNTIF($AN11:$AN11,"AB")+COUNTIF($AN11:$AN11,"FE")+COUNTIF($AN11:$AN11,"LM"))) | BF11: =SUMPRODUCT(($I11:$AM11="M")*6+($I11:$AM11="T")*6+($I11:$AM11="D")*12+($I11:$AM11="N")*12+($I11:$AM11="NT")*6+($I11:$AM11="C")*10+($I11:$AM11="A")*8+($I11:$AM11="J")*5+($I11:$AM11="CEP")*4+($I11:$AM11="CP")*6+($I11:$AM11="CRO")*6+($I11:$AM11="M+")*6+($I11:$AM11="T+")*6+($I11:$AM11="D+")*12+($I11:$AM11="N+")*12+($I11:$AM11="Dm+")*12+($I11:$AM11="Dt+")*12+($I11:$AM11="Tm-")*6+($I11:$AM11="Mt-")*6) | BG11: =SUMPRODUCT($I$4:$AM$4,($I11:$AM11="M")*6+($I11:$AM11="T")*6+($I11:$AM11="D")*12+($I11:$AM11="N")*12+($I11:$AM11="NT")*6+($I11:$AM11="C")*10+($I11:$AM11="A")*8+($I11:$AM11="J")*5+($I11:$AM11="CEP")*4+($I11:$AM11="CP")*6+($I11:$AM11="CRO")*6+($I11:$AM11="M+")*6+($I11:$AM11="T+")*6+($I11:$AM11="D+")*12+($I11:$AM11="N+")*12+($I11:$AM11="Dm+")*12+($I11:$AM11="Dt+")*12+($I11:$AM11="Tm-")*6+($I11:$AM11="Mt-")*6) | BH11: =SUMPRODUCT($I$5:$AM$5,(($I11:$AM11="N")+($I11:$AM11="N+"))) | BI11: =SUMPRODUCT($I$6:$AM$6,($I11:$AM11="M")*6+($I11:$AM11="T")*6+($I11:$AM11="D")*12+($I11:$AM11="N")*12+($I11:$AM11="NT")*6+($I11:$AM11="C")*10+($I11:$AM11="A")*8+($I11:$AM11="J")*5+($I11:$AM11="CEP")*4+($I11:$AM11="CP")*6+($I11:$AM11="CRO")*6+($I11:$AM11="M+")*6+($I11:$AM11="T+")*6+($I11:$AM11="D+")*12+($I11:$AM11="N+")*12+($I11:$AM11="Dm+")*12+($I11:$AM11="Dt+")*12+($I11:$AM11="Tm-")*6+($I11:$AM11="Mt-")*6) | BJ11: =ROUND(B11*4.43,0) | BK11: =BF11-BJ11 | BL11: =SUMPRODUCT((($C11:$AL11="N")+($C11:$AL11="N+"))*(($D11:$AM11="M")+($D11:$AM11="D")+($D11:$AM11="C")+($D11:$AM11="CEP")+($D11:$AM11="M+")+($D11:$AM11="D+")+($D11:$AM11="Dm+")+($D11:$AM11="Dt+")+($D11:$AM11="Mt-"))) | BM11: =SUMPRODUCT((($C11:$AL11="N")+($C11:$AL11="N+"))*(($D11:$AM11="T")+($D11:$AM11="T+")+($D11:$AM11="Tm-"))) | BN11: =IFERROR(INDEX(CONFIG!$B$44:$D$46,MATCH($B11,CONFIG!$A$44:$A$46,0),IF(COUNTIF($I11:$AM11,"FE")>=10,1,IF(COUNTIF($I11:$AM11,"FE")>=1,2,3))),"") | BO11: =IF(BN11="","",MAX(0,BG11-BN11*CONFIG!$E$44)) | BP11: =MAX(AT11,AV11,AX11,AZ11,BB11,BD11) | BQ11: 2 · rotina | BR11: 7
A12: DebAlves | B12: 40 | U12: M | V12: M | W12: D | X12: M | Y12: T | AA12: M | AB12: M | AC12: M | AD12: M | AE12: M | AG12: D | AH12: M | AI12: D | AJ12: M | AK12: D | AL12: M | AN12: =IFERROR(INDEX(FEV!I$8:I$73,MATCH($A12,FEV!$A$8:$A$73,0))&"","") | AT12: =SUMPRODUCT(($F12:$L12="M")*6+($F12:$L12="T")*6+($F12:$L12="D")*12+($F12:$L12="N")*12+($F12:$L12="NT")*6+($F12:$L12="C")*10+($F12:$L12="A")*8+($F12:$L12="J")*5+($F12:$L12="CEP")*4+($F12:$L12="CP")*6+($F12:$L12="CRO")*6+($F12:$L12="M+")*6+($F12:$L12="T+")*6+($F12:$L12="D+")*12+($F12:$L12="N+")*12+($F12:$L12="Dm+")*12+($F12:$L12="Dt+")*12+($F12:$L12="Tm-")*6+($F12:$L12="Mt-")*6) | AU12: =AT12-MAX(0,IFERROR(INDEX(CADASTRO!$I$4:$I$80,MATCH($A12,CADASTRO!$A$4:$A$80,0)),$B12)-CONFIG!$B$50*(COUNTIF($F12:$L12,"AB")+COUNTIF($F12:$L12,"FE")+COUNTIF($F12:$L12,"LM"))) | AV12: =SUMPRODUCT(($M12:$S12="M")*6+($M12:$S12="T")*6+($M12:$S12="D")*12+($M12:$S12="N")*12+($M12:$S12="NT")*6+($M12:$S12="C")*10+($M12:$S12="A")*8+($M12:$S12="J")*5+($M12:$S12="CEP")*4+($M12:$S12="CP")*6+($M12:$S12="CRO")*6+($M12:$S12="M+")*6+($M12:$S12="T+")*6+($M12:$S12="D+")*12+($M12:$S12="N+")*12+($M12:$S12="Dm+")*12+($M12:$S12="Dt+")*12+($M12:$S12="Tm-")*6+($M12:$S12="Mt-")*6) | AW12: =AV12-MAX(0,IFERROR(INDEX(CADASTRO!$I$4:$I$80,MATCH($A12,CADASTRO!$A$4:$A$80,0)),$B12)-CONFIG!$B$50*(COUNTIF($M12:$S12,"AB")+COUNTIF($M12:$S12,"FE")+COUNTIF($M12:$S12,"LM"))) | AX12: =SUMPRODUCT(($T12:$Z12="M")*6+($T12:$Z12="T")*6+($T12:$Z12="D")*12+($T12:$Z12="N")*12+($T12:$Z12="NT")*6+($T12:$Z12="C")*10+($T12:$Z12="A")*8+($T12:$Z12="J")*5+($T12:$Z12="CEP")*4+($T12:$Z12="CP")*6+($T12:$Z12="CRO")*6+($T12:$Z12="M+")*6+($T12:$Z12="T+")*6+($T12:$Z12="D+")*12+($T12:$Z12="N+")*12+($T12:$Z12="Dm+")*12+($T12:$Z12="Dt+")*12+($T12:$Z12="Tm-")*6+($T12:$Z12="Mt-")*6) | AY12: =AX12-MAX(0,IFERROR(INDEX(CADASTRO!$I$4:$I$80,MATCH($A12,CADASTRO!$A$4:$A$80,0)),$B12)-CONFIG!$B$50*(COUNTIF($T12:$Z12,"AB")+COUNTIF($T12:$Z12,"FE")+COUNTIF($T12:$Z12,"LM"))) | AZ12: =SUMPRODUCT(($AA12:$AG12="M")*6+($AA12:$AG12="T")*6+($AA12:$AG12="D")*12+($AA12:$AG12="N")*12+($AA12:$AG12="NT")*6+($AA12:$AG12="C")*10+($AA12:$AG12="A")*8+($AA12:$AG12="J")*5+($AA12:$AG12="CEP")*4+($AA12:$AG12="CP")*6+($AA12:$AG12="CRO")*6+($AA12:$AG12="M+")*6+($AA12:$AG12="T+")*6+($AA12:$AG12="D+")*12+($AA12:$AG12="N+")*12+($AA12:$AG12="Dm+")*12+($AA12:$AG12="Dt+")*12+($AA12:$AG12="Tm-")*6+($AA12:$AG12="Mt-")*6) | BA12: =AZ12-MAX(0,IFERROR(INDEX(CADASTRO!$I$4:$I$80,MATCH($A12,CADASTRO!$A$4:$A$80,0)),$B12)-CONFIG!$B$50*(COUNTIF($AA12:$AG12,"AB")+COUNTIF($AA12:$AG12,"FE")+COUNTIF($AA12:$AG12,"LM"))) | BB12: =SUMPRODUCT(($AH12:$AM12="M")*6+($AH12:$AM12="T")*6+($AH12:$AM12="D")*12+($AH12:$AM12="N")*12+($AH12:$AM12="NT")*6+($AH12:$AM12="C")*10+($AH12:$AM12="A")*8+($AH12:$AM12="J")*5+($AH12:$AM12="CEP")*4+($AH12:$AM12="CP")*6+($AH12:$AM12="CRO")*6+($AH12:$AM12="M+")*6+($AH12:$AM12="T+")*6+($AH12:$AM12="D+")*12+($AH12:$AM12="N+")*12+($AH12:$AM12="Dm+")*12+($AH12:$AM12="Dt+")*12+($AH12:$AM12="Tm-")*6+($AH12:$AM12="Mt-")*6)+SUMPRODUCT(($AN12:$AN12="M")*6+($AN12:$AN12="T")*6+($AN12:$AN12="D")*12+($AN12:$AN12="N")*12+($AN12:$AN12="NT")*6+($AN12:$AN12="C")*10+($AN12:$AN12="A")*8+($AN12:$AN12="J")*5+($AN12:$AN12="CEP")*4+($AN12:$AN12="CP")*6+($AN12:$AN12="CRO")*6+($AN12:$AN12="M+")*6+($AN12:$AN12="T+")*6+($AN12:$AN12="D+")*12+($AN12:$AN12="N+")*12+($AN12:$AN12="Dm+")*12+($AN12:$AN12="Dt+")*12+($AN12:$AN12="Tm-")*6+($AN12:$AN12="Mt-")*6) | BC12: =BB12-MAX(0,IFERROR(INDEX(CADASTRO!$I$4:$I$80,MATCH($A12,CADASTRO!$A$4:$A$80,0)),$B12)-CONFIG!$B$50*(COUNTIF($AH12:$AM12,"AB")+COUNTIF($AH12:$AM12,"FE")+COUNTIF($AH12:$AM12,"LM")+COUNTIF($AN12:$AN12,"AB")+COUNTIF($AN12:$AN12,"FE")+COUNTIF($AN12:$AN12,"LM"))) | BF12: =SUMPRODUCT(($I12:$AM12="M")*6+($I12:$AM12="T")*6+($I12:$AM12="D")*12+($I12:$AM12="N")*12+($I12:$AM12="NT")*6+($I12:$AM12="C")*10+($I12:$AM12="A")*8+($I12:$AM12="J")*5+($I12:$AM12="CEP")*4+($I12:$AM12="CP")*6+($I12:$AM12="CRO")*6+($I12:$AM12="M+")*6+($I12:$AM12="T+")*6+($I12:$AM12="D+")*12+($I12:$AM12="N+")*12+($I12:$AM12="Dm+")*12+($I12:$AM12="Dt+")*12+($I12:$AM12="Tm-")*6+($I12:$AM12="Mt-")*6) | BG12: =SUMPRODUCT($I$4:$AM$4,($I12:$AM12="M")*6+($I12:$AM12="T")*6+($I12:$AM12="D")*12+($I12:$AM12="N")*12+($I12:$AM12="NT")*6+($I12:$AM12="C")*10+($I12:$AM12="A")*8+($I12:$AM12="J")*5+($I12:$AM12="CEP")*4+($I12:$AM12="CP")*6+($I12:$AM12="CRO")*6+($I12:$AM12="M+")*6+($I12:$AM12="T+")*6+($I12:$AM12="D+")*12+($I12:$AM12="N+")*12+($I12:$AM12="Dm+")*12+($I12:$AM12="Dt+")*12+($I12:$AM12="Tm-")*6+($I12:$AM12="Mt-")*6) | BH12: =SUMPRODUCT($I$5:$AM$5,(($I12:$AM12="N")+($I12:$AM12="N+"))) | BI12: =SUMPRODUCT($I$6:$AM$6,($I12:$AM12="M")*6+($I12:$AM12="T")*6+($I12:$AM12="D")*12+($I12:$AM12="N")*12+($I12:$AM12="NT")*6+($I12:$AM12="C")*10+($I12:$AM12="A")*8+($I12:$AM12="J")*5+($I12:$AM12="CEP")*4+($I12:$AM12="CP")*6+($I12:$AM12="CRO")*6+($I12:$AM12="M+")*6+($I12:$AM12="T+")*6+($I12:$AM12="D+")*12+($I12:$AM12="N+")*12+($I12:$AM12="Dm+")*12+($I12:$AM12="Dt+")*12+($I12:$AM12="Tm-")*6+($I12:$AM12="Mt-")*6) | BJ12: =ROUND(B12*4.43,0) | BK12: =BF12-BJ12 | BL12: =SUMPRODUCT((($C12:$AL12="N")+($C12:$AL12="N+"))*(($D12:$AM12="M")+($D12:$AM12="D")+($D12:$AM12="C")+($D12:$AM12="CEP")+($D12:$AM12="M+")+($D12:$AM12="D+")+($D12:$AM12="Dm+")+($D12:$AM12="Dt+")+($D12:$AM12="Mt-"))) | BM12: =SUMPRODUCT((($C12:$AL12="N")+($C12:$AL12="N+"))*(($D12:$AM12="T")+($D12:$AM12="T+")+($D12:$AM12="Tm-"))) | BN12: =IFERROR(INDEX(CONFIG!$B$44:$D$46,MATCH($B12,CONFIG!$A$44:$A$46,0),IF(COUNTIF($I12:$AM12,"FE")>=10,1,IF(COUNTIF($I12:$AM12,"FE")>=1,2,3))),"") | BO12: =IF(BN12="","",MAX(0,BG12-BN12*CONFIG!$E$44)) | BP12: =MAX(AT12,AV12,AX12,AZ12,BB12,BD12) | BQ12: 2 · rotina | BR12: 7
A13: Vinicius | B13: 36 | L13: M | M13: M | N13: M | O13: M | P13: M | Q13: M | S13: N | T13: M | U13: M | V13: M | W13: M | X13: M | AA13: M | AB13: M | AC13: M | AD13: M | AE13: M | AF13: N | AH13: M | AI13: M | AJ13: M | AK13: M | AL13: M | AN13: =IFERROR(INDEX(FEV!I$8:I$73,MATCH($A13,FEV!$A$8:$A$73,0))&"","") | AT13: =SUMPRODUCT(($F13:$L13="M")*6+($F13:$L13="T")*6+($F13:$L13="D")*12+($F13:$L13="N")*12+($F13:$L13="NT")*6+($F13:$L13="C")*10+($F13:$L13="A")*8+($F13:$L13="J")*5+($F13:$L13="CEP")*4+($F13:$L13="CP")*6+($F13:$L13="CRO")*6+($F13:$L13="M+")*6+($F13:$L13="T+")*6+($F13:$L13="D+")*12+($F13:$L13="N+")*12+($F13:$L13="Dm+")*12+($F13:$L13="Dt+")*12+($F13:$L13="Tm-")*6+($F13:$L13="Mt-")*6) | AU13: =AT13-MAX(0,IFERROR(INDEX(CADASTRO!$I$4:$I$80,MATCH($A13,CADASTRO!$A$4:$A$80,0)),$B13)-CONFIG!$B$50*(COUNTIF($F13:$L13,"AB")+COUNTIF($F13:$L13,"FE")+COUNTIF($F13:$L13,"LM"))) | AV13: =SUMPRODUCT(($M13:$S13="M")*6+($M13:$S13="T")*6+($M13:$S13="D")*12+($M13:$S13="N")*12+($M13:$S13="NT")*6+($M13:$S13="C")*10+($M13:$S13="A")*8+($M13:$S13="J")*5+($M13:$S13="CEP")*4+($M13:$S13="CP")*6+($M13:$S13="CRO")*6+($M13:$S13="M+")*6+($M13:$S13="T+")*6+($M13:$S13="D+")*12+($M13:$S13="N+")*12+($M13:$S13="Dm+")*12+($M13:$S13="Dt+")*12+($M13:$S13="Tm-")*6+($M13:$S13="Mt-")*6) | AW13: =AV13-MAX(0,IFERROR(INDEX(CADASTRO!$I$4:$I$80,MATCH($A13,CADASTRO!$A$4:$A$80,0)),$B13)-CONFIG!$B$50*(COUNTIF($M13:$S13,"AB")+COUNTIF($M13:$S13,"FE")+COUNTIF($M13:$S13,"LM"))) | AX13: =SUMPRODUCT(($T13:$Z13="M")*6+($T13:$Z13="T")*6+($T13:$Z13="D")*12+($T13:$Z13="N")*12+($T13:$Z13="NT")*6+($T13:$Z13="C")*10+($T13:$Z13="A")*8+($T13:$Z13="J")*5+($T13:$Z13="CEP")*4+($T13:$Z13="CP")*6+($T13:$Z13="CRO")*6+($T13:$Z13="M+")*6+($T13:$Z13="T+")*6+($T13:$Z13="D+")*12+($T13:$Z13="N+")*12+($T13:$Z13="Dm+")*12+($T13:$Z13="Dt+")*12+($T13:$Z13="Tm-")*6+($T13:$Z13="Mt-")*6) | AY13: =AX13-MAX(0,IFERROR(INDEX(CADASTRO!$I$4:$I$80,MATCH($A13,CADASTRO!$A$4:$A$80,0)),$B13)-CONFIG!$B$50*(COUNTIF($T13:$Z13,"AB")+COUNTIF($T13:$Z13,"FE")+COUNTIF($T13:$Z13,"LM"))) | AZ13: =SUMPRODUCT(($AA13:$AG13="M")*6+($AA13:$AG13="T")*6+($AA13:$AG13="D")*12+($AA13:$AG13="N")*12+($AA13:$AG13="NT")*6+($AA13:$AG13="C")*10+($AA13:$AG13="A")*8+($AA13:$AG13="J")*5+($AA13:$AG13="CEP")*4+($AA13:$AG13="CP")*6+($AA13:$AG13="CRO")*6+($AA13:$AG13="M+")*6+($AA13:$AG13="T+")*6+($AA13:$AG13="D+")*12+($AA13:$AG13="N+")*12+($AA13:$AG13="Dm+")*12+($AA13:$AG13="Dt+")*12+($AA13:$AG13="Tm-")*6+($AA13:$AG13="Mt-")*6) | BA13: =AZ13-MAX(0,IFERROR(INDEX(CADASTRO!$I$4:$I$80,MATCH($A13,CADASTRO!$A$4:$A$80,0)),$B13)-CONFIG!$B$50*(COUNTIF($AA13:$AG13,"AB")+COUNTIF($AA13:$AG13,"FE")+COUNTIF($AA13:$AG13,"LM"))) | BB13: =SUMPRODUCT(($AH13:$AM13="M")*6+($AH13:$AM13="T")*6+($AH13:$AM13="D")*12+($AH13:$AM13="N")*12+($AH13:$AM13="NT")*6+($AH13:$AM13="C")*10+($AH13:$AM13="A")*8+($AH13:$AM13="J")*5+($AH13:$AM13="CEP")*4+($AH13:$AM13="CP")*6+($AH13:$AM13="CRO")*6+($AH13:$AM13="M+")*6+($AH13:$AM13="T+")*6+($AH13:$AM13="D+")*12+($AH13:$AM13="N+")*12+($AH13:$AM13="Dm+")*12+($AH13:$AM13="Dt+")*12+($AH13:$AM13="Tm-")*6+($AH13:$AM13="Mt-")*6)+SUMPRODUCT(($AN13:$AN13="M")*6+($AN13:$AN13="T")*6+($AN13:$AN13="D")*12+($AN13:$AN13="N")*12+($AN13:$AN13="NT")*6+($AN13:$AN13="C")*10+($AN13:$AN13="A")*8+($AN13:$AN13="J")*5+($AN13:$AN13="CEP")*4+($AN13:$AN13="CP")*6+($AN13:$AN13="CRO")*6+($AN13:$AN13="M+")*6+($AN13:$AN13="T+")*6+($AN13:$AN13="D+")*12+($AN13:$AN13="N+")*12+($AN13:$AN13="Dm+")*12+($AN13:$AN13="Dt+")*12+($AN13:$AN13="Tm-")*6+($AN13:$AN13="Mt-")*6) | BC13: =BB13-MAX(0,IFERROR(INDEX(CADASTRO!$I$4:$I$80,MATCH($A13,CADASTRO!$A$4:$A$80,0)),$B13)-CONFIG!$B$50*(COUNTIF($AH13:$AM13,"AB")+COUNTIF($AH13:$AM13,"FE")+COUNTIF($AH13:$AM13,"LM")+COUNTIF($AN13:$AN13,"AB")+COUNTIF($AN13:$AN13,"FE")+COUNTIF($AN13:$AN13,"LM"))) | BF13: =SUMPRODUCT(($I13:$AM13="M")*6+($I13:$AM13="T")*6+($I13:$AM13="D")*12+($I13:$AM13="N")*12+($I13:$AM13="NT")*6+($I13:$AM13="C")*10+($I13:$AM13="A")*8+($I13:$AM13="J")*5+($I13:$AM13="CEP")*4+($I13:$AM13="CP")*6+($I13:$AM13="CRO")*6+($I13:$AM13="M+")*6+($I13:$AM13="T+")*6+($I13:$AM13="D+")*12+($I13:$AM13="N+")*12+($I13:$AM13="Dm+")*12+($I13:$AM13="Dt+")*12+($I13:$AM13="Tm-")*6+($I13:$AM13="Mt-")*6) | BG13: =SUMPRODUCT($I$4:$AM$4,($I13:$AM13="M")*6+($I13:$AM13="T")*6+($I13:$AM13="D")*12+($I13:$AM13="N")*12+($I13:$AM13="NT")*6+($I13:$AM13="C")*10+($I13:$AM13="A")*8+($I13:$AM13="J")*5+($I13:$AM13="CEP")*4+($I13:$AM13="CP")*6+($I13:$AM13="CRO")*6+($I13:$AM13="M+")*6+($I13:$AM13="T+")*6+($I13:$AM13="D+")*12+($I13:$AM13="N+")*12+($I13:$AM13="Dm+")*12+($I13:$AM13="Dt+")*12+($I13:$AM13="Tm-")*6+($I13:$AM13="Mt-")*6) | BH13: =SUMPRODUCT($I$5:$AM$5,(($I13:$AM13="N")+($I13:$AM13="N+"))) | BI13: =SUMPRODUCT($I$6:$AM$6,($I13:$AM13="M")*6+($I13:$AM13="T")*6+($I13:$AM13="D")*12+($I13:$AM13="N")*12+($I13:$AM13="NT")*6+($I13:$AM13="C")*10+($I13:$AM13="A")*8+($I13:$AM13="J")*5+($I13:$AM13="CEP")*4+($I13:$AM13="CP")*6+($I13:$AM13="CRO")*6+($I13:$AM13="M+")*6+($I13:$AM13="T+")*6+($I13:$AM13="D+")*12+($I13:$AM13="N+")*12+($I13:$AM13="Dm+")*12+($I13:$AM13="Dt+")*12+($I13:$AM13="Tm-")*6+($I13:$AM13="Mt-")*6) | BJ13: =ROUND(B13*4.43,0) | BK13: =BF13-BJ13 | BL13: =SUMPRODUCT((($C13:$AL13="N")+($C13:$AL13="N+"))*(($D13:$AM13="M")+($D13:$AM13="D")+($D13:$AM13="C")+($D13:$AM13="CEP")+($D13:$AM13="M+")+($D13:$AM13="D+")+($D13:$AM13="Dm+")+($D13:$AM13="Dt+")+($D13:$AM13="Mt-"))) | BM13: =SUMPRODUCT((($C13:$AL13="N")+($C13:$AL13="N+"))*(($D13:$AM13="T")+($D13:$AM13="T+")+($D13:$AM13="Tm-"))) | BN13: =IFERROR(INDEX(CONFIG!$B$44:$D$46,MATCH($B13,CONFIG!$A$44:$A$46,0),IF(COUNTIF($I13:$AM13,"FE")>=10,1,IF(COUNTIF($I13:$AM13,"FE")>=1,2,3))),"") | BO13: =IF(BN13="","",MAX(0,BG13-BN13*CONFIG!$E$44)) | BP13: =MAX(AT13,AV13,AX13,AZ13,BB13,BD13) | BQ13: 2 · rotina | BR13: 7
