Workbook

Sheet DASHBOARD
B2: colo ritmo · hospital da criança de brasília
B3: painel da escala · outubro de 2026
B5: toda contagem aqui é fórmula das abas mensais — digitou um código na escala, este painel se refaz sozinho.
B8: o mês que vai publicar · outubro
B9: BURACOS DE COBERTURA NO MÊS | E9: DIAS COMPLETOS | G9: ALERTAS DE 18H | I9: FORA DA META | K9: CONVOCAÇÕES | M9: HORAS NOTURNAS
B10: =IF(COUNTA(OUT!$C$8:$AG$73)>0,SUM(OUT!$C$78:$AG$78)+SUM(OUT!$C$79:$AG$79)+SUM(OUT!$C$80:$AG$80),"") | E10: =IF(COUNTA(OUT!$C$8:$AG$73)>0,SUMPRODUCT((OUT!$C$78:$AG$78+OUT!$C$79:$AG$79+OUT!$C$80:$AG$80=0)*(OUT!$C$78:$AG$78<>"")),"")&"/"&COUNT(OUT!$C$2:$AG$2) | G10: =SUM(OUT!$AN$8:$AN$73) | I10: =SUMPRODUCT(--(ABS(OUT!$AM$8:$AM$73)>12)) | K10: =IFERROR(SUM(CONVOCAÇÕES!$B$6:$B$60),0) | M10: =COUNTIF(OUT!$C$8:$AG$73,"N")*7+COUNTIF(OUT!$C$8:$AG$73,"NT")*3
B12: soma de tudo que falta pro mínimo, somando os três turnos e os 31 dias | E12: dias em que os três turnos bateram o mínimo | G12: o alvo é zero · art. 66 CLT | I12: pessoas com mais de 12h de desvio, pra cima ou pra baixo | K12: entraram fora da própria preferência · geram crédito | M12: janela 22h–05h · insumo do adicional noturno
B14: o ano · para comparar
B15: as regras duras apertaram junto com a mudança de abril, e funcionou: os alertas de 18h caíram de ~15 por mês para ~2.
B17: mês | C17: alertas 18h | D17: buracos | E17: dias completos | F17: manhã | G17: tarde | H17: noite | I17: horas noturnas
B18: jan | C18: ='DADOS DASH'!B5 | D18: ='DADOS DASH'!C5 | E18: ='DADOS DASH'!D5 | F18: ='DADOS DASH'!E5 | G18: ='DADOS DASH'!F5 | H18: ='DADOS DASH'!G5 | I18: ='DADOS DASH'!I5
B19: fev | C19: ='DADOS DASH'!B6 | D19: ='DADOS DASH'!C6 | E19: ='DADOS DASH'!D6 | F19: ='DADOS DASH'!E6 | G19: ='DADOS DASH'!F6 | H19: ='DADOS DASH'!G6 | I19: ='DADOS DASH'!I6
B20: mar | C20: ='DADOS DASH'!B7 | D20: ='DADOS DASH'!C7 | E20: ='DADOS DASH'!D7 | F20: ='DADOS DASH'!E7 | G20: ='DADOS DASH'!F7 | H20: ='DADOS DASH'!G7 | I20: ='DADOS DASH'!I7
B21: abr | C21: ='DADOS DASH'!B8 | D21: ='DADOS DASH'!C8 | E21: ='DADOS DASH'!D8 | F21: ='DADOS DASH'!E8 | G21: ='DADOS DASH'!F8 | H21: ='DADOS DASH'!G8 | I21: ='DADOS DASH'!I8
B22: mai | C22: ='DADOS DASH'!B9 | D22: ='DADOS DASH'!C9 | E22: ='DADOS DASH'!D9 | F22: ='DADOS DASH'!E9 | G22: ='DADOS DASH'!F9 | H22: ='DADOS DASH'!G9 | I22: ='DADOS DASH'!I9
B23: jun | C23: ='DADOS DASH'!B10 | D23: ='DADOS DASH'!C10 | E23: ='DADOS DASH'!D10 | F23: ='DADOS DASH'!E10 | G23: ='DADOS DASH'!F10 | H23: ='DADOS DASH'!G10 | I23: ='DADOS DASH'!I10
B24: jul | C24: ='DADOS DASH'!B11 | D24: ='DADOS DASH'!C11 | E24: ='DADOS DASH'!D11 | F24: ='DADOS DASH'!E11 | G24: ='DADOS DASH'!F11 | H24: ='DADOS DASH'!G11 | I24: ='DADOS DASH'!I11
B25: ago | C25: ='DADOS DASH'!B12 | D25: ='DADOS DASH'!C12 | E25: ='DADOS DASH'!D12 | F25: ='DADOS DASH'!E12 | G25: ='DADOS DASH'!F12 | H25: ='DADOS DASH'!G12 | I25: ='DADOS DASH'!I12
B26: set | C26: ='DADOS DASH'!B13 | D26: ='DADOS DASH'!C13 | E26: ='DADOS DASH'!D13 | F26: ='DADOS DASH'!E13 | G26: ='DADOS DASH'!F13 | H26: ='DADOS DASH'!G13 | I26: ='DADOS DASH'!I13
B27: out | C27: ='DADOS DASH'!B14 | D27: ='DADOS DASH'!C14 | E27: ='DADOS DASH'!D14 | F27: ='DADOS DASH'!E14 | G27: ='DADOS DASH'!F14 | H27: ='DADOS DASH'!G14 | I27: ='DADOS DASH'!I14
B28: nov | C28: ='DADOS DASH'!B15 | D28: ='DADOS DASH'!C15 | E28: ='DADOS DASH'!D15 | F28: ='DADOS DASH'!E15 | G28: ='DADOS DASH'!F15 | H28: ='DADOS DASH'!G15 | I28: ='DADOS DASH'!I15
B29: dez | C29: ='DADOS DASH'!B16 | D29: ='DADOS DASH'!C16 | E29: ='DADOS DASH'!D16 | F29: ='DADOS DASH'!E16 | G29: ='DADOS DASH'!F16 | H29: ='DADOS DASH'!G16 | I29: ='DADOS DASH'!I16

Sheet LEIA-ME
A1: escala UTI HCB · 2026 — planilha unificada v4
A3: o que é
B4: O ano inteiro num arquivo: 12 abas mensais com a escala real, o painel comparativo do ano, a tradução pros códigos do Senior e o validador das regras que são lei. Tudo o que é contagem é fórmula — digitou o código na aba do mês, a cobertura, a carga horária, o saldo e os alertas se refazem sozinhos.
A6: legenda dos códigos
A7: código | B7: turno | C7: horário | D7: horas | E7: Senior
A8: M | B8: manhã | C8: 07–13h | D8: 6 | E8: 2
A9: T | B9: tarde | C9: 13–19h | D9: 6 | E9: 239
A10: D | B10: dia 12h | C10: 07–19h | D10: 12 | E10: 40
A11: N | B11: noite 12h | C11: 19–07h | D11: 12 | E11: 41
A12: NT | B12: noitinha | C12: 19–01h | D12: 6 | E12: 349
A13: C | B13: 10h chefia | C13: 8–12 + 13–19h | D13: 10 | E13: 47
A14: A | B14: administrativo | C14: 8h diurno | D14: 8 | E14: 11
A15: J | B15: 5h Janaina | C15: 08–13h | D15: 5 | E15: 78
A16: E | B16: 4h CEP | C16: 08–12h | D16: 4 | E16: 6
A17: P | B17: paliativo | C17: 07–13h | D17: 6 | E17: —
A18: R | B18: CRO | C18: 13–19h | D18: 6 | E18: —
A19: FE | B19: férias | C19: — | D19: — | E19: Férias
A20: LM | B20: licença | C20: — | D20: — | E20: LM
A21: AB | B21: abono niver | C21: — | D21: — | E21: —
A22: antigos | B22: Até abril de 2026 os códigos eram outros: 110 = M (manhã) · 82 = D (dia 12h) · 83 = N (noite 12h) · 10 = J (5h, virou 78). A mudança de abril passou a usar 2/40/41.
A24: as abas
A25: CADASTRO | B25: quem é quem: carga horária, restrições duras, sexta-noite e fds extra. É a fonte dos nomes de todas as abas mensais.
A26: CONFIG | B26: as regras como dado: cobertura mínima, cota de fds em mês com férias, tabela de códigos e as regras duras com o artigo da CLF. Mudou aqui, mudou na planilha toda.
A27: JAN a DEZ | B27: a escala: matriz médico × dia. No rodapé, a lotação de cada turno em cada dia e quanto falta pro mínimo. À direita, por pessoa: carga do mês, fds, sexta-noite, feriado, meta, saldo e os dois alertas de jornada.
A28: PAINEL ANO | B28: o comparativo do ano: saldo, fds, sexta-noite e feriado de cada pessoa mês a mês, com acumulado. Onde existe a contagem manual antiga, ela aparece ao lado pra conferência.
A29: SENIOR | B29: escolha o mês em B1 e a matriz inteira sai traduzida nos códigos do RH, pronta pra lançar.
A30: VALIDADOR | B30: o que fere regra dura, separado em ESTRUTURAL (é a forma do contrato, decisão de política) e PONTUAL (erro daquele mês).
A31: ATENDIMENTO / CONVOCAÇÕES | B31: o mês vivo: o que foi atendido de cada pedido e por quê, e quem foi convocado fora da preferência, com o critério público.
A33: de onde vem cada mês — leia antes de comparar
A34: JAN | B34: reconstruído da grade 'ESCALA FINAL JANEIRO 2026' — a grade começa no dia 2
A35: FEV | B35: códigos Senior (códigos antigos 110/82/83)
A36: MAR | B36: códigos Senior (códigos antigos 110/82/83)
A37: ABR | B37: códigos Senior — mudança de abril: passa a 2/40/41
A38: MAI | B38: reconstruído da grade; dias 1–2 vêm do arquivo de abril; DIA 3 NÃO EXISTE em nenhum arquivo
A39: JUN | B39: reconstruído da grade 'Escala junho - UTI HCB'
A40: JUL | B40: códigos Senior
A41: AGO | B41: códigos Senior
A42: SET | B42: códigos Senior
A43: OUT | B43: escala montada pelo escala_out_v3.py — cobertura 100%, 48 convocações por critério público
A44: NOV | B44: a montar
...

Sheet CADASTRO
A1: cadastro · quem é quem | D1: 66 pessoas ativas
A3: médico | B3: nome completo | C3: CH | D3: grupo | E3: restrições duras | F3: sexta-noite | G3: fds extra | H3: observações
A4: Fred | B4: Frederico Pires | C4: 36 | D4: chefia | E4: seg+ter 10h chefia; qua+qui manhã | F4: não | G4: não | H4: CH zerada nas contagens de plantão
A5: Milena | B5: Milena | C5: 36 | D5: chefia | E5: seg/ter/qua manhã; qui 10h chefia | F5: não | G5: não
A6: Pabdo | B6: Paula Abdo | C6: 36 | D6: chefia | E6: rotina/coordenação | F6: não | G6: não | H6: aniversário 29/10, sem folga
A7: MSalomão | B7: Marina Salomão | C7: 40 | D7: chefia | E7: manhãs seg–sex; PROIBIDO dom noite emendando (18h invertido) → sáb noite; NÃO sexta tarde | F7: não | G7: não | H7: bloqueio 42/42/36 · rodízio fds 15/15 com Vinicius, contínuo no ano · abre outubro com 42h
A8: DebAlves | B8: Deborah Alves | C8: 40 | D8: chefia | E8: manhãs seg–sex + tardes p/ completar (ter, senão qui) | F8: não | G8: não | H8: bloqueio 42/42/36 · cota fds 24h
A9: Vinicius | B9: Vinicius Bezerra | C9: 36 | D9: chefia | E9: manhãs seg–sex + fds 15/15 com MSalomão | F9: não | G9: sim | H9: bloqueio 30/42 · FÉRIAS 12–26/10
A10: Amelio | B10: Fernanda Amelio | C10: 36 | D10: chefia | E10: SEM NOTURNOS (atestado desde abr/25); seg–sex manhãs | F10: não | G10: não | H10: fora 24–31/10 (BHN)
A11: Murilo | B11: Murilo | C11: 36 | D11: rotina | E11: rotina onco manhãs; fds 15/15 sábado noturno | F11: não | G11: não | H11: voltou de licença
A12: Janaina | B12: Janaina Rabelo | C12: 30 | D12: 30h | E12: SÓ 8–13h (código 78); sem noturnos; seg–sáb | F12: não | G12: não | H12: é sempre a 10ª da manhã de sábado; NUNCA domingo
A13: Aline | B13: Aline Saliba | C13: 40 | D13: 36h | E13: CEP 4h: 1ª terça manhã do mês; demais semanas seg ou qui | F13: não | G13: sim | H13: 36 assist + 4 CEP · FÉRIAS 19/10–02/11
A14: CaAbreu | B14: Camila Abreu | C14: 36 | D14: 36h | E14: fixa qua dia (+seg dia); NÃO qui noite | F14: não | G14: sim
A15: Danielle | B15: Danielle Tanajura | C15: 36 | D15: 36h | E15: fixa qua noite (+qui noite); só noites | F15: não | G15: não | H15: não lançar sexta-noite (já fez muitas)
A16: Fabiula | B16: Fabiula Czameski | C16: 36 | D16: 36h | E16: só noites; ter/qua/qui alternando com ter/qua/dom | F16: sim | G16: não
A17: Isabella | B17: Isabella Mazzaro | C17: 36 | D17: 36h | E17: fixo sex dia; NÃO qua noite, NÃO qui noite; evitar sáb noite | F17: sim | G17: não | H17: INVERTEU em out: não pode mais sextas
A18: JuBrito | B18: Julliana Brito | C18: 30 | D18: 30h | E18: fixa ter dia, qua manhã, qui dia, sex manhã; NÃO segundas (Sobradinho) | F18: não | G18: não | H18: CH 30h CONFIRMADO (era 36) · +6h fds a cada 2 meses · não quer o feriado 12/10
A19: Kariny | B19: Fernanda Kariny | C19: 36 | D19: 36h | E19: fixa seg/ter/qui dia; NÃO quartas; 6h avulsa só de manhã | F19: não | G19: não | H19: repouso 09–12/10 (procedimento)
A20: Mayana | B20: Mayana Leal | C20: 36 | D20: 36h | E20: fixa ter dia, qui dia; NÃO seg/qua/sex tarde | F20: não | G20: não
A21: Neyde | B21: Neyde Brito | C21: 36 | D21: 36h | E21: fixa ter+qua noite + 1º/3º/4º dom noite; NÃO qui/sex/sáb noite (HMIB) | F21: não | G21: sim | H21: férias 19/10 + 15 dias
A22: Roberta | B22: Roberta Iglesias | C22: 36 | D22: 36h | E22: coringa | F22: não | G22: sim
A23: LuAlice | B23: Luciana Alice | C23: 36 | D23: 36h | E23: fixa ter+qui noite, sáb noite no fds; SÓ noturnos (+tardes CRO) | F23: sim | G23: não | H23: NUNCA lançar banco de horas · 36h temporária, 12h/mês CRO · não lançar sextas 02 e 30/10 N
A24: Amanda | B24: Amanda Braga | C24: 30 | D24: 30h | E24: alterna qui noite / qua dia | F24: sim | G24: sim | H24: férias até ~12/10 · NÃO escalar fds extra em outubro (fez horas a mais em set)
A25: Fernando | B25: Fernando Filardi | C25: 30 | D25: 30h | E25: fixo seg noite, qua+qui manhã, sáb manhã | F25: não | G25: não | H25: troca sáb 17/10 → dom 04/10 manhã; oferece sexta-noite 23/10
A26: João | B26: João | C26: 30 | D26: 30h | E26: NÃO manhãs, NÃO segundas, NÃO sábados; ter/qui/sex tarde + qua noite | F26: não | G26: não | H26: extrapola fds · férias até ~06/10
A27: JuCoutinho | B27: Juliana Coutinho | C27: 30 | D27: 30h | E27: fixa qua diurno, sextas manhãs; NÃO qui dia | F27: não | G27: não | H27: prefere 6h em vez de 12h
A28: LeLemos | B28: Leticia Lemos | C28: 30 | D28: 30h | E28: seg dia ↔ seg noite alternando | F28: 1/mês | G28: sim | H28: férias até 05/10
A29: Leomara | B29: Leomara | C29: 24 | D29: 24h | E29: só seg/ter manhã, qua noite, sex dia/noite, fds; evitar 2 noturnos/semana | F29: não | G29: não | H29: 24h desde ago
A30: Marilia | B30: Marilia | C30: 30 | D30: 30h | E30: ter dia ↔ qua dia 15/15; sexta só manhã; NÃO segundas (Luzia) | F30: não | G30: não | H30: pediu a sexta-noite dela em out (16/10) em vez de nov
A31: Raylander | B31: Daniel Raylander | C31: 30 | D31: 30h | E31: NÃO seg tarde, qui manhã, sex dia (faculdade); aceita noturnos seguidos | F31: não | G31: SIM obrigatório | H31: casado com Ariadne — nunca no mesmo turno
A32: Ricardo | B32: Ricardo | C32: 30 | D32: 30h | E32: fixo ter noite (sai da fixa quando faz SN/fds) | F32: não | G32: sim | H32: escalar junto com Nishioka
A33: Rosana | B33: Rosana | C33: 30 | D33: 30h | E33: só manhãs e noites/noitinhas (mãe em quimio): SEM tardes, SEM 12h diurnas | F33: não | G33: não | H33: férias até ~12/10
A34: AnaSeverino | B34: Ana Severino | C34: 24 | D34: 24h | E34: seg (M/dia/N) ou qui noite; NÃO tardes | F34: não | G34: sim
A35: Anna | B35: Anna Jorge | C35: 24 | D35: 24h | E35: NÃO seg manhã/noite, ter tarde, qui inteiro, sex tarde, dom noite | F35: não | G35: não | H35: habitual seg/qua tarde
A36: Ariadne | B36: Ariadne | C36: 24 | D36: 24h | E36: casada com Raylander — NUNCA no mesmo turno | F36: não | G36: não | H36: volta de licença 26/10, CH passa a 24h
A37: Beatriz | B37: Beatriz | C37: 24 | D37: 24h | E37: mora parte em SP; manda blocos de indisponibilidade | F37: sim | G37: não
A38: Bruna | B38: Bruna | C38: 24 | D38: 24h | E38: habitual terças (dia ou noite) | F38: não | G38: não | H38: férias a partir de 19/10
A39: Constantino | B39: Fernanda Constantino | C39: 24 | D39: 24h | E39: seg noite OU ter noite, qui noite; NÃO quartas; evitar noites consecutivas | F39: não | G39: sim | H39: trabalhou 07/09 → folgar 12/10; não escalar fds 10–11
A40: DebMatias | B40: Debora Matias | C40: 24 | D40: 24h | E40: ter/qua/sex dia (não toda sexta); noturno só ter noite | F40: não | G40: não
A41: Denise | B41: Denise | C41: 24 | D41: 24h | E41: fixa seg/ter/qui manhã; NÃO tardes; evitar 2 noturnos/semana | F41: não | G41: não
...

Sheet CONFIG
A1: config · as regras como dado | D1: mudou aqui, muda na planilha toda
A3: em vigor · de out/26 | B3: manhã | C3: tarde | D3: noite
A4: útil | B4: 14 | C4: 10 | D4: 7 | F4: Regra da Mari de 13/08/26, vale da escala de outubro em diante. Substitui 11/8/7 e 9/7/6. A 10ª da manhã de sábado é sempre a Janaina (8–13h); ela nunca faz domingo. Feriado escala como o dia da semana em que cai.
A5: sábado | B5: 10 | C5: 8 | D5: 7
A6: domingo | B6: 9 | C6: 8 | D6: 7
A8: até set/26 · histórico | B8: manhã | C8: tarde | D8: noite
A9: útil | B9: 11 | C9: 8 | D9: 7 | F9: Os meses de janeiro a setembro são medidos por ESTA regra. Cobrar deles o mínimo novo seria exigir do passado uma regra que ainda não existia.
A10: sábado | B10: 9 | C10: 7 | D10: 6
A11: domingo | B11: 9 | C11: 7 | D11: 6
A13: tabela de códigos
A14: letra | B14: Senior | C14: horas | D14: conta manhã | E14: conta tarde | F14: conta noite | G14: turno
A15: M | B15: 2 | C15: 6 | D15: 1 | E15: 0 | F15: 0 | G15: manhã · 07–13h
A16: T | B16: 239 | C16: 6 | D16: 0 | E16: 1 | F16: 0 | G16: tarde · 13–19h
A17: D | B17: 40 | C17: 12 | D17: 1 | E17: 1 | F17: 0 | G17: dia 12h · 07–19h
A18: N | B18: 41 | C18: 12 | D18: 0 | E18: 0 | F18: 1 | G18: noite 12h · 19–07h
A19: NT | B19: 349 | C19: 6 | D19: 0 | E19: 0 | F19: 1 | G19: noitinha · 19–01h
A20: C | B20: 47 | C20: 10 | D20: 1 | E20: 1 | F20: 0 | G20: 10h chefia · 8–12 + 13–19h
A21: A | B21: 11 | C21: 8 | D21: 0 | E21: 0 | F21: 0 | G21: administrativo · 8h diurno
A22: J | B22: 78 | C22: 5 | D22: 1 | E22: 0 | F22: 0 | G22: 5h Janaina · 08–13h
A23: E | B23: 6 | C23: 4 | D23: 1 | E23: 0 | F23: 0 | G23: 4h CEP · 08–12h
A24: P | C24: 6 | D24: 0 | E24: 0 | F24: 0 | G24: paliativo · 07–13h
A25: R | C25: 6 | D25: 0 | E25: 0 | F25: 0 | G25: CRO · 13–19h
A26: FE | B26: Férias | C26: 0 | D26: 0 | E26: 0 | F26: 0 | G26: férias · —
A27: LM | B27: LM | C27: 0 | D27: 0 | E27: 0 | F27: 0 | G27: licença · —
A28: AB | C28: 0 | D28: 0 | E28: 0 | F28: 0 | G28: abono niver · —
A30: cota de fds em mês com férias
A31: CH semanal | B31: férias 2 sem | C31: férias 1 sem | D31: sem férias
A32: 36 | B32: 24 | C32: 30 | D32: 36
A33: 30 | B33: 18 | C33: 24 | D33: 30
A34: 24 | B34: 12 | C34: 18 | D34: 24
A36: feriados de 2026 | E36: Feriado escala como o DIA DA SEMANA em que cai — não reduz a lotação exigida (doc de referência §2). Confirmado na prática: nos sete feriados de 2026 até setembro a manhã rodou com 15 a 20 pessoas, e a rotina/chefia trabalhou em todos eles (4 a 6 pessoas). O que muda no feriado é a contabilidade, que tem coluna própria e equalização anual.
A37: data | B37: sigla | C37: feriado
A38: 01/01 (qui) | B38: 1ºjan | C38: Confraternização
A39: 16/02 (seg) | B39: carn | C39: Carnaval
A40: 17/02 (ter) | B40: carn | C40: Carnaval
A41: 03/04 (sex) | B41: paix | C41: Paixão
A42: 21/04 (ter) | B42: tira | C42: Tiradentes
A43: 01/05 (sex) | B43: trab | C43: Dia do Trabalhador
A44: 04/06 (qui) | B44: corp | C44: Corpus Christi
A45: 07/09 (seg) | B45: indep | C45: Independência
...

Sheet JAN
A1: janeiro · 2026 | C1: reconstruído da grade 'ESCALA FINAL JANEIRO 2026' — a grade começa no dia 2
C2: 1 | D2: 2 | E2: 3 | F2: 4 | G2: 5 | H2: 6 | I2: 7 | J2: 8 | K2: 9 | L2: 10 | M2: 11 | N2: 12 | O2: 13 | P2: 14 | Q2: 15 | R2: 16 | S2: 17 | T2: 18 | U2: 19 | V2: 20 | W2: 21 | X2: 22 | Y2: 23 | Z2: 24 | AA2: 25 | AB2: 26 | AC2: 27 | AD2: 28 | AE2: 29 | AF2: 30 | AG2: 31
C3: 1ºjan | D3: sex | E3: sáb | F3: dom | G3: seg | H3: ter | I3: qua | J3: qui | K3: sex | L3: sáb | M3: dom | N3: seg | O3: ter | P3: qua | Q3: qui | R3: sex | S3: sáb | T3: dom | U3: seg | V3: ter | W3: qua | X3: qui | Y3: sex | Z3: sáb | AA3: dom | AB3: seg | AC3: ter | AD3: qua | AE3: qui | AF3: sex | AG3: sáb
A4: máscara fds | C4: 0 | D4: 0 | E4: 1 | F4: 1 | G4: 0 | H4: 0 | I4: 0 | J4: 0 | K4: 0 | L4: 1 | M4: 1 | N4: 0 | O4: 0 | P4: 0 | Q4: 0 | R4: 0 | S4: 1 | T4: 1 | U4: 0 | V4: 0 | W4: 0 | X4: 0 | Y4: 0 | Z4: 1 | AA4: 1 | AB4: 0 | AC4: 0 | AD4: 0 | AE4: 0 | AF4: 0 | AG4: 1
A5: máscara sexta | C5: 0 | D5: 1 | E5: 0 | F5: 0 | G5: 0 | H5: 0 | I5: 0 | J5: 0 | K5: 1 | L5: 0 | M5: 0 | N5: 0 | O5: 0 | P5: 0 | Q5: 0 | R5: 1 | S5: 0 | T5: 0 | U5: 0 | V5: 0 | W5: 0 | X5: 0 | Y5: 1 | Z5: 0 | AA5: 0 | AB5: 0 | AC5: 0 | AD5: 0 | AE5: 0 | AF5: 1 | AG5: 0
A6: máscara feriado | C6: 1 | D6: 0 | E6: 0 | F6: 0 | G6: 0 | H6: 0 | I6: 0 | J6: 0 | K6: 0 | L6: 0 | M6: 0 | N6: 0 | O6: 0 | P6: 0 | Q6: 0 | R6: 0 | S6: 0 | T6: 0 | U6: 0 | V6: 0 | W6: 0 | X6: 0 | Y6: 0 | Z6: 0 | AA6: 0 | AB6: 0 | AC6: 0 | AD6: 0 | AE6: 0 | AF6: 0 | AG6: 0
A7: médico | B7: CH | AH7: CH mês | AI7: fds | AJ7: SxN | AK7: feriado | AL7: meta | AM7: saldo | AN7: 18h⚠ | AO7: N→T
A8: Fred | B8: 36 | D8: M | G8: M | H8: M | I8: M | J8: M | K8: M | N8: M | O8: M | P8: M | Q8: M | R8: M | U8: M | V8: M | W8: M | X8: M | Y8: M | AH8: =SUMPRODUCT(($C8:$AG8="M")*6+($C8:$AG8="T")*6+($C8:$AG8="D")*12+($C8:$AG8="N")*12+($C8:$AG8="NT")*6+($C8:$AG8="C")*10+($C8:$AG8="A")*8+($C8:$AG8="J")*5+($C8:$AG8="E")*4+($C8:$AG8="P")*6+($C8:$AG8="R")*6) | AI8: =SUMPRODUCT($C$4:$AG$4,($C8:$AG8="M")*6+($C8:$AG8="T")*6+($C8:$AG8="D")*12+($C8:$AG8="N")*12+($C8:$AG8="NT")*6+($C8:$AG8="C")*10+($C8:$AG8="A")*8+($C8:$AG8="J")*5+($C8:$AG8="E")*4+($C8:$AG8="P")*6+($C8:$AG8="R")*6) | AJ8: =SUMPRODUCT($C$5:$AG$5,($C8:$AG8="N")*1) | AK8: =SUMPRODUCT($C$6:$AG$6,($C8:$AG8="M")*6+($C8:$AG8="T")*6+($C8:$AG8="D")*12+($C8:$AG8="N")*12+($C8:$AG8="NT")*6+($C8:$AG8="C")*10+($C8:$AG8="A")*8+($C8:$AG8="J")*5+($C8:$AG8="E")*4+($C8:$AG8="P")*6+($C8:$AG8="R")*6) | AL8: =ROUND(B8*4.43,0) | AM8: =AH8-AL8 | AN8: =SUMPRODUCT(($C8:$AF8="N")*(($D8:$AG8="M")+($D8:$AG8="E")+($D8:$AG8="C")+($D8:$AG8="D"))) | AO8: =SUMPRODUCT(($C8:$AF8="N")*($D8:$AG8="T"))
A9: Milena | B9: 36 | D9: M | G9: M | H9: M | I9: M | J9: M | K9: M | N9: M | O9: M | P9: M | Q9: M | R9: M | U9: M | V9: M | W9: M | X9: M | Y9: M | AB9: M | AC9: M | AD9: M | AE9: M | AF9: M | AH9: =SUMPRODUCT(($C9:$AG9="M")*6+($C9:$AG9="T")*6+($C9:$AG9="D")*12+($C9:$AG9="N")*12+($C9:$AG9="NT")*6+($C9:$AG9="C")*10+($C9:$AG9="A")*8+($C9:$AG9="J")*5+($C9:$AG9="E")*4+($C9:$AG9="P")*6+($C9:$AG9="R")*6) | AI9: =SUMPRODUCT($C$4:$AG$4,($C9:$AG9="M")*6+($C9:$AG9="T")*6+($C9:$AG9="D")*12+($C9:$AG9="N")*12+($C9:$AG9="NT")*6+($C9:$AG9="C")*10+($C9:$AG9="A")*8+($C9:$AG9="J")*5+($C9:$AG9="E")*4+($C9:$AG9="P")*6+($C9:$AG9="R")*6) | AJ9: =SUMPRODUCT($C$5:$AG$5,($C9:$AG9="N")*1) | AK9: =SUMPRODUCT($C$6:$AG$6,($C9:$AG9="M")*6+($C9:$AG9="T")*6+($C9:$AG9="D")*12+($C9:$AG9="N")*12+($C9:$AG9="NT")*6+($C9:$AG9="C")*10+($C9:$AG9="A")*8+($C9:$AG9="J")*5+($C9:$AG9="E")*4+($C9:$AG9="P")*6+($C9:$AG9="R")*6) | AL9: =ROUND(B9*4.43,0) | AM9: =AH9-AL9 | AN9: =SUMPRODUCT(($C9:$AF9="N")*(($D9:$AG9="M")+($D9:$AG9="E")+($D9:$AG9="C")+($D9:$AG9="D"))) | AO9: =SUMPRODUCT(($C9:$AF9="N")*($D9:$AG9="T"))
A10: Pabdo | B10: 36 | AH10: =SUMPRODUCT(($C10:$AG10="M")*6+($C10:$AG10="T")*6+($C10:$AG10="D")*12+($C10:$AG10="N")*12+($C10:$AG10="NT")*6+($C10:$AG10="C")*10+($C10:$AG10="A")*8+($C10:$AG10="J")*5+($C10:$AG10="E")*4+($C10:$AG10="P")*6+($C10:$AG10="R")*6) | AI10: =SUMPRODUCT($C$4:$AG$4,($C10:$AG10="M")*6+($C10:$AG10="T")*6+($C10:$AG10="D")*12+($C10:$AG10="N")*12+($C10:$AG10="NT")*6+($C10:$AG10="C")*10+($C10:$AG10="A")*8+($C10:$AG10="J")*5+($C10:$AG10="E")*4+($C10:$AG10="P")*6+($C10:$AG10="R")*6) | AJ10: =SUMPRODUCT($C$5:$AG$5,($C10:$AG10="N")*1) | AK10: =SUMPRODUCT($C$6:$AG$6,($C10:$AG10="M")*6+($C10:$AG10="T")*6+($C10:$AG10="D")*12+($C10:$AG10="N")*12+($C10:$AG10="NT")*6+($C10:$AG10="C")*10+($C10:$AG10="A")*8+($C10:$AG10="J")*5+($C10:$AG10="E")*4+($C10:$AG10="P")*6+($C10:$AG10="R")*6) | AL10: =ROUND(B10*4.43,0) | AM10: =AH10-AL10 | AN10: =SUMPRODUCT(($C10:$AF10="N")*(($D10:$AG10="M")+($D10:$AG10="E")+($D10:$AG10="C")+($D10:$AG10="D"))) | AO10: =SUMPRODUCT(($C10:$AF10="N")*($D10:$AG10="T"))
A11: MSalomão | B11: 40 | D11: D | F11: M | G11: M | H11: D | I11: M | J11: M | K11: M | N11: M | O11: M | P11: M | Q11: M | R11: M | T11: N | U11: M | V11: D | W11: M | X11: D | Y11: M | AB11: M | AC11: M | AD11: M | AE11: M | AF11: M | AG11: N | AH11: =SUMPRODUCT(($C11:$AG11="M")*6+($C11:$AG11="T")*6+($C11:$AG11="D")*12+($C11:$AG11="N")*12+($C11:$AG11="NT")*6+($C11:$AG11="C")*10+($C11:$AG11="A")*8+($C11:$AG11="J")*5+($C11:$AG11="E")*4+($C11:$AG11="P")*6+($C11:$AG11="R")*6) | AI11: =SUMPRODUCT($C$4:$AG$4,($C11:$AG11="M")*6+($C11:$AG11="T")*6+($C11:$AG11="D")*12+($C11:$AG11="N")*12+($C11:$AG11="NT")*6+($C11:$AG11="C")*10+($C11:$AG11="A")*8+($C11:$AG11="J")*5+($C11:$AG11="E")*4+($C11:$AG11="P")*6+($C11:$AG11="R")*6) | AJ11: =SUMPRODUCT($C$5:$AG$5,($C11:$AG11="N")*1) | AK11: =SUMPRODUCT($C$6:$AG$6,($C11:$AG11="M")*6+($C11:$AG11="T")*6+($C11:$AG11="D")*12+($C11:$AG11="N")*12+($C11:$AG11="NT")*6+($C11:$AG11="C")*10+($C11:$AG11="A")*8+($C11:$AG11="J")*5+($C11:$AG11="E")*4+($C11:$AG11="P")*6+($C11:$AG11="R")*6) | AL11: =ROUND(B11*4.43,0) | AM11: =AH11-AL11 | AN11: =SUMPRODUCT(($C11:$AF11="N")*(($D11:$AG11="M")+($D11:$AG11="E")+($D11:$AG11="C")+($D11:$AG11="D"))) | AO11: =SUMPRODUCT(($C11:$AF11="N")*($D11:$AG11="T"))
A12: DebAlves | B12: 40 | O12: M | P12: M | Q12: D | R12: M | S12: T | U12: M | V12: M | W12: M | X12: M | Y12: M | AA12: D | AB12: M | AC12: D | AD12: M | AE12: D | AF12: M | AH12: =SUMPRODUCT(($C12:$AG12="M")*6+($C12:$AG12="T")*6+($C12:$AG12="D")*12+($C12:$AG12="N")*12+($C12:$AG12="NT")*6+($C12:$AG12="C")*10+($C12:$AG12="A")*8+($C12:$AG12="J")*5+($C12:$AG12="E")*4+($C12:$AG12="P")*6+($C12:$AG12="R")*6) | AI12: =SUMPRODUCT($C$4:$AG$4,($C12:$AG12="M")*6+($C12:$AG12="T")*6+($C12:$AG12="D")*12+($C12:$AG12="N")*12+($C12:$AG12="NT")*6+($C12:$AG12="C")*10+($C12:$AG12="A")*8+($C12:$AG12="J")*5+($C12:$AG12="E")*4+($C12:$AG12="P")*6+($C12:$AG12="R")*6) | AJ12: =SUMPRODUCT($C$5:$AG$5,($C12:$AG12="N")*1) | AK12: =SUMPRODUCT($C$6:$AG$6,($C12:$AG12="M")*6+($C12:$AG12="T")*6+($C12:$AG12="D")*12+($C12:$AG12="N")*12+($C12:$AG12="NT")*6+($C12:$AG12="C")*10+($C12:$AG12="A")*8+($C12:$AG12="J")*5+($C12:$AG12="E")*4+($C12:$AG12="P")*6+($C12:$AG12="R")*6) | AL12: =ROUND(B12*4.43,0) | AM12: =AH12-AL12 | AN12: =SUMPRODUCT(($C12:$AF12="N")*(($D12:$AG12="M")+($D12:$AG12="E")+($D12:$AG12="C")+($D12:$AG12="D"))) | AO12: =SUMPRODUCT(($C12:$AF12="N")*($D12:$AG12="T"))
A13: Vinicius | B13: 36 | F13: M | G13: M | H13: M | I13: M | J13: M | K13: M | M13: N | N13: M | O13: M | P13: M | Q13: M | R13: M | U13: M | V13: M | W13: M | X13: M | Y13: M | Z13: N | AB13: M | AC13: M | AD13: M | AE13: M | AF13: M | AH13: =SUMPRODUCT(($C13:$AG13="M")*6+($C13:$AG13="T")*6+($C13:$AG13="D")*12+($C13:$AG13="N")*12+($C13:$AG13="NT")*6+($C13:$AG13="C")*10+($C13:$AG13="A")*8+($C13:$AG13="J")*5+($C13:$AG13="E")*4+($C13:$AG13="P")*6+($C13:$AG13="R")*6) | AI13: =SUMPRODUCT($C$4:$AG$4,($C13:$AG13="M")*6+($C13:$AG13="T")*6+($C13:$AG13="D")*12+($C13:$AG13="N")*12+($C13:$AG13="NT")*6+($C13:$AG13="C")*10+($C13:$AG13="A")*8+($C13:$AG13="J")*5+($C13:$AG13="E")*4+($C13:$AG13="P")*6+($C13:$AG13="R")*6) | AJ13: =SUMPRODUCT($C$5:$AG$5,($C13:$AG13="N")*1) | AK13: =SUMPRODUCT($C$6:$AG$6,($C13:$AG13="M")*6+($C13:$AG13="T")*6+($C13:$AG13="D")*12+($C13:$AG13="N")*12+($C13:$AG13="NT")*6+($C13:$AG13="C")*10+($C13:$AG13="A")*8+($C13:$AG13="J")*5+($C13:$AG13="E")*4+($C13:$AG13="P")*6+($C13:$AG13="R")*6) | AL13: =ROUND(B13*4.43,0) | AM13: =AH13-AL13 | AN13: =SUMPRODUCT(($C13:$AF13="N")*(($D13:$AG13="M")+($D13:$AG13="E")+($D13:$AG13="C")+($D13:$AG13="D"))) | AO13: =SUMPRODUCT(($C13:$AF13="N")*($D13:$AG13="T"))
A14: Amelio | B14: 36 | D14: D | G14: T | I14: T | J14: D | L14: N | N14: T | P14: T | Q14: N | R14: T | U14: T | X14: D | Y14: T | Z14: N | AA14: T | AE14: D | AF14: N | AG14: T | AH14: =SUMPRODUCT(($C14:$AG14="M")*6+($C14:$AG14="T")*6+($C14:$AG14="D")*12+($C14:$AG14="N")*12+($C14:$AG14="NT")*6+($C14:$AG14="C")*10+($C14:$AG14="A")*8+($C14:$AG14="J")*5+($C14:$AG14="E")*4+($C14:$AG14="P")*6+($C14:$AG14="R")*6) | AI14: =SUMPRODUCT($C$4:$AG$4,($C14:$AG14="M")*6+($C14:$AG14="T")*6+($C14:$AG14="D")*12+($C14:$AG14="N")*12+($C14:$AG14="NT")*6+($C14:$AG14="C")*10+($C14:$AG14="A")*8+($C14:$AG14="J")*5+($C14:$AG14="E")*4+($C14:$AG14="P")*6+($C14:$AG14="R")*6) | AJ14: =SUMPRODUCT($C$5:$AG$5,($C14:$AG14="N")*1) | AK14: =SUMPRODUCT($C$6:$AG$6,($C14:$AG14="M")*6+($C14:$AG14="T")*6+($C14:$AG14="D")*12+($C14:$AG14="N")*12+($C14:$AG14="NT")*6+($C14:$AG14="C")*10+($C14:$AG14="A")*8+($C14:$AG14="J")*5+($C14:$AG14="E")*4+($C14:$AG14="P")*6+($C14:$AG14="R")*6) | AL14: =ROUND(B14*4.43,0) | AM14: =AH14-AL14 | AN14: =SUMPRODUCT(($C14:$AF14="N")*(($D14:$AG14="M")+($D14:$AG14="E")+($D14:$AG14="C")+($D14:$AG14="D"))) | AO14: =SUMPRODUCT(($C14:$AF14="N")*($D14:$AG14="T"))
A15: Murilo | B15: 36 | D15: M | G15: M | H15: M | I15: M | J15: M | K15: M | L15: N | N15: M | O15: M | P15: M | Q15: M | R15: M | S15: NT | U15: M | V15: M | W15: M | X15: M | Y15: M | Z15: N | AB15: M | AC15: M | AD15: M | AE15: D | AF15: M | AH15: =SUMPRODUCT(($C15:$AG15="M")*6+($C15:$AG15="T")*6+($C15:$AG15="D")*12+($C15:$AG15="N")*12+($C15:$AG15="NT")*6+($C15:$AG15="C")*10+($C15:$AG15="A")*8+($C15:$AG15="J")*5+($C15:$AG15="E")*4+($C15:$AG15="P")*6+($C15:$AG15="R")*6) | AI15: =SUMPRODUCT($C$4:$AG$4,($C15:$AG15="M")*6+($C15:$AG15="T")*6+($C15:$AG15="D")*12+($C15:$AG15="N")*12+($C15:$AG15="NT")*6+($C15:$AG15="C")*10+($C15:$AG15="A")*8+($C15:$AG15="J")*5+($C15:$AG15="E")*4+($C15:$AG15="P")*6+($C15:$AG15="R")*6) | AJ15: =SUMPRODUCT($C$5:$AG$5,($C15:$AG15="N")*1) | AK15: =SUMPRODUCT($C$6:$AG$6,($C15:$AG15="M")*6+($C15:$AG15="T")*6+($C15:$AG15="D")*12+($C15:$AG15="N")*12+($C15:$AG15="NT")*6+($C15:$AG15="C")*10+($C15:$AG15="A")*8+($C15:$AG15="J")*5+($C15:$AG15="E")*4+($C15:$AG15="P")*6+($C15:$AG15="R")*6) | AL15: =ROUND(B15*4.43,0) | AM15: =AH15-AL15 | AN15: =SUMPRODUCT(($C15:$AF15="N")*(($D15:$AG15="M")+($D15:$AG15="E")+($D15:$AG15="C")+($D15:$AG15="D"))) | AO15: =SUMPRODUCT(($C15:$AF15="N")*($D15:$AG15="T"))
A16: Janaina | B16: 30 | AH16: =SUMPRODUCT(($C16:$AG16="M")*6+($C16:$AG16="T")*6+($C16:$AG16="D")*12+($C16:$AG16="N")*12+($C16:$AG16="NT")*6+($C16:$AG16="C")*10+($C16:$AG16="A")*8+($C16:$AG16="J")*5+($C16:$AG16="E")*4+($C16:$AG16="P")*6+($C16:$AG16="R")*6) | AI16: =SUMPRODUCT($C$4:$AG$4,($C16:$AG16="M")*6+($C16:$AG16="T")*6+($C16:$AG16="D")*12+($C16:$AG16="N")*12+($C16:$AG16="NT")*6+($C16:$AG16="C")*10+($C16:$AG16="A")*8+($C16:$AG16="J")*5+($C16:$AG16="E")*4+($C16:$AG16="P")*6+($C16:$AG16="R")*6) | AJ16: =SUMPRODUCT($C$5:$AG$5,($C16:$AG16="N")*1) | AK16: =SUMPRODUCT($C$6:$AG$6,($C16:$AG16="M")*6+($C16:$AG16="T")*6+($C16:$AG16="D")*12+($C16:$AG16="N")*12+($C16:$AG16="NT")*6+($C16:$AG16="C")*10+($C16:$AG16="A")*8+($C16:$AG16="J")*5+($C16:$AG16="E")*4+($C16:$AG16="P")*6+($C16:$AG16="R")*6) | AL16: =ROUND(B16*4.43,0) | AM16: =AH16-AL16 | AN16: =SUMPRODUCT(($C16:$AF16="N")*(($D16:$AG16="M")+($D16:$AG16="E")+($D16:$AG16="C")+($D16:$AG16="D"))) | AO16: =SUMPRODUCT(($C16:$AF16="N")*($D16:$AG16="T"))
A17: Aline | B17: 40 | D17: T | E17: T | G17: T | H17: D | I17: T | J17: T | K17: N | N17: N | O17: D | P17: T | Q17: N | U17: T | V17: N | W17: M | Z17: M | AA17: N | AB17: D | AC17: N | AD17: T | AE17: N | AH17: =SUMPRODUCT(($C17:$AG17="M")*6+($C17:$AG17="T")*6+($C17:$AG17="D")*12+($C17:$AG17="N")*12+($C17:$AG17="NT")*6+($C17:$AG17="C")*10+($C17:$AG17="A")*8+($C17:$AG17="J")*5+($C17:$AG17="E")*4+($C17:$AG17="P")*6+($C17:$AG17="R")*6) | AI17: =SUMPRODUCT($C$4:$AG$4,($C17:$AG17="M")*6+($C17:$AG17="T")*6+($C17:$AG17="D")*12+($C17:$AG17="N")*12+($C17:$AG17="NT")*6+($C17:$AG17="C")*10+($C17:$AG17="A")*8+($C17:$AG17="J")*5+($C17:$AG17="E")*4+($C17:$AG17="P")*6+($C17:$AG17="R")*6) | AJ17: =SUMPRODUCT($C$5:$AG$5,($C17:$AG17="N")*1) | AK17: =SUMPRODUCT($C$6:$AG$6,($C17:$AG17="M")*6+($C17:$AG17="T")*6+($C17:$AG17="D")*12+($C17:$AG17="N")*12+($C17:$AG17="NT")*6+($C17:$AG17="C")*10+($C17:$AG17="A")*8+($C17:$AG17="J")*5+($C17:$AG17="E")*4+($C17:$AG17="P")*6+($C17:$AG17="R")*6) | AL17: =ROUND(B17*4.43,0) | AM17: =AH17-AL17 | AN17: =SUMPRODUCT(($C17:$AF17="N")*(($D17:$AG17="M")+($D17:$AG17="E")+($D17:$AG17="C")+($D17:$AG17="D"))) | AO17: =SUMPRODUCT(($C17:$AF17="N")*($D17:$AG17="T"))
A18: CaAbreu | B18: 36 | D18: N | F18: D | G18: D | I18: D | K18: N | N18: D | P18: D | S18: D | AH18: =SUMPRODUCT(($C18:$AG18="M")*6+($C18:$AG18="T")*6+($C18:$AG18="D")*12+($C18:$AG18="N")*12+($C18:$AG18="NT")*6+($C18:$AG18="C")*10+($C18:$AG18="A")*8+($C18:$AG18="J")*5+($C18:$AG18="E")*4+($C18:$AG18="P")*6+($C18:$AG18="R")*6) | AI18: =SUMPRODUCT($C$4:$AG$4,($C18:$AG18="M")*6+($C18:$AG18="T")*6+($C18:$AG18="D")*12+($C18:$AG18="N")*12+($C18:$AG18="NT")*6+($C18:$AG18="C")*10+($C18:$AG18="A")*8+($C18:$AG18="J")*5+($C18:$AG18="E")*4+($C18:$AG18="P")*6+($C18:$AG18="R")*6) | AJ18: =SUMPRODUCT($C$5:$AG$5,($C18:$AG18="N")*1) | AK18: =SUMPRODUCT($C$6:$AG$6,($C18:$AG18="M")*6+($C18:$AG18="T")*6+($C18:$AG18="D")*12+($C18:$AG18="N")*12+($C18:$AG18="NT")*6+($C18:$AG18="C")*10+($C18:$AG18="A")*8+($C18:$AG18="J")*5+($C18:$AG18="E")*4+($C18:$AG18="P")*6+($C18:$AG18="R")*6) | AL18: =ROUND(B18*4.43,0) | AM18: =AH18-AL18 | AN18: =SUMPRODUCT(($C18:$AF18="N")*(($D18:$AG18="M")+($D18:$AG18="E")+($D18:$AG18="C")+($D18:$AG18="D"))) | AO18: =SUMPRODUCT(($C18:$AF18="N")*($D18:$AG18="T"))
A19: Danielle | B19: 36 | G19: T | I19: NT | J19: N | M19: N | N19: N | P19: N | S19: N | W19: N | Y19: N | AA19: N | AD19: N | AE19: N | AH19: =SUMPRODUCT(($C19:$AG19="M")*6+($C19:$AG19="T")*6+($C19:$AG19="D")*12+($C19:$AG19="N")*12+($C19:$AG19="NT")*6+($C19:$AG19="C")*10+($C19:$AG19="A")*8+($C19:$AG19="J")*5+($C19:$AG19="E")*4+($C19:$AG19="P")*6+($C19:$AG19="R")*6) | AI19: =SUMPRODUCT($C$4:$AG$4,($C19:$AG19="M")*6+($C19:$AG19="T")*6+($C19:$AG19="D")*12+($C19:$AG19="N")*12+($C19:$AG19="NT")*6+($C19:$AG19="C")*10+($C19:$AG19="A")*8+($C19:$AG19="J")*5+($C19:$AG19="E")*4+($C19:$AG19="P")*6+($C19:$AG19="R")*6) | AJ19: =SUMPRODUCT($C$5:$AG$5,($C19:$AG19="N")*1) | AK19: =SUMPRODUCT($C$6:$AG$6,($C19:$AG19="M")*6+($C19:$AG19="T")*6+($C19:$AG19="D")*12+($C19:$AG19="N")*12+($C19:$AG19="NT")*6+($C19:$AG19="C")*10+($C19:$AG19="A")*8+($C19:$AG19="J")*5+($C19:$AG19="E")*4+($C19:$AG19="P")*6+($C19:$AG19="R")*6) | AL19: =ROUND(B19*4.43,0) | AM19: =AH19-AL19 | AN19: =SUMPRODUCT(($C19:$AF19="N")*(($D19:$AG19="M")+($D19:$AG19="E")+($D19:$AG19="C")+($D19:$AG19="D"))) | AO19: =SUMPRODUCT(($C19:$AF19="N")*($D19:$AG19="T"))
A20: Fabiula | B20: 36 | D20: N | I20: N | J20: N | L20: N | P20: N | Q20: N | T20: N | W20: N | X20: N | Y20: N | AD20: N | AG20: N | AH20: =SUMPRODUCT(($C20:$AG20="M")*6+($C20:$AG20="T")*6+($C20:$AG20="D")*12+($C20:$AG20="N")*12+($C20:$AG20="NT")*6+($C20:$AG20="C")*10+($C20:$AG20="A")*8+($C20:$AG20="J")*5+($C20:$AG20="E")*4+($C20:$AG20="P")*6+($C20:$AG20="R")*6) | AI20: =SUMPRODUCT($C$4:$AG$4,($C20:$AG20="M")*6+($C20:$AG20="T")*6+($C20:$AG20="D")*12+($C20:$AG20="N")*12+($C20:$AG20="NT")*6+($C20:$AG20="C")*10+($C20:$AG20="A")*8+($C20:$AG20="J")*5+($C20:$AG20="E")*4+($C20:$AG20="P")*6+($C20:$AG20="R")*6) | AJ20: =SUMPRODUCT($C$5:$AG$5,($C20:$AG20="N")*1) | AK20: =SUMPRODUCT($C$6:$AG$6,($C20:$AG20="M")*6+($C20:$AG20="T")*6+($C20:$AG20="D")*12+($C20:$AG20="N")*12+($C20:$AG20="NT")*6+($C20:$AG20="C")*10+($C20:$AG20="A")*8+($C20:$AG20="J")*5+($C20:$AG20="E")*4+($C20:$AG20="P")*6+($C20:$AG20="R")*6) | AL20: =ROUND(B20*4.43,0) | AM20: =AH20-AL20 | AN20: =SUMPRODUCT(($C20:$AF20="N")*(($D20:$AG20="M")+($D20:$AG20="E")+($D20:$AG20="C")+($D20:$AG20="D"))) | AO20: =SUMPRODUCT(($C20:$AF20="N")*($D20:$AG20="T"))
A21: Isabella | B21: 36 | D21: T | E21: D | F21: M | G21: T | I21: M | J21: M | L21: M | M21: N | N21: T | O21: N | Q21: M | R21: D | U21: T | V21: D | Y21: D | AB21: T | AC21: D | AD21: M | AE21: N | AH21: =SUMPRODUCT(($C21:$AG21="M")*6+($C21:$AG21="T")*6+($C21:$AG21="D")*12+($C21:$AG21="N")*12+($C21:$AG21="NT")*6+($C21:$AG21="C")*10+($C21:$AG21="A")*8+($C21:$AG21="J")*5+($C21:$AG21="E")*4+($C21:$AG21="P")*6+($C21:$AG21="R")*6) | AI21: =SUMPRODUCT($C$4:$AG$4,($C21:$AG21="M")*6+($C21:$AG21="T")*6+($C21:$AG21="D")*12+($C21:$AG21="N")*12+($C21:$AG21="NT")*6+($C21:$AG21="C")*10+($C21:$AG21="A")*8+($C21:$AG21="J")*5+($C21:$AG21="E")*4+($C21:$AG21="P")*6+($C21:$AG21="R")*6) | AJ21: =SUMPRODUCT($C$5:$AG$5,($C21:$AG21="N")*1) | AK21: =SUMPRODUCT($C$6:$AG$6,($C21:$AG21="M")*6+($C21:$AG21="T")*6+($C21:$AG21="D")*12+($C21:$AG21="N")*12+($C21:$AG21="NT")*6+($C21:$AG21="C")*10+($C21:$AG21="A")*8+($C21:$AG21="J")*5+($C21:$AG21="E")*4+($C21:$AG21="P")*6+($C21:$AG21="R")*6) | AL21: =ROUND(B21*4.43,0) | AM21: =AH21-AL21 | AN21: =SUMPRODUCT(($C21:$AF21="N")*(($D21:$AG21="M")+($D21:$AG21="E")+($D21:$AG21="C")+($D21:$AG21="D"))) | AO21: =SUMPRODUCT(($C21:$AF21="N")*($D21:$AG21="T"))
A22: JuBrito | B22: 30 | D22: D | E22: T | F22: D | V22: D | X22: T | Y22: N | AC22: D | AD22: D | AE22: M | AG22: M | AH22: =SUMPRODUCT(($C22:$AG22="M")*6+($C22:$AG22="T")*6+($C22:$AG22="D")*12+($C22:$AG22="N")*12+($C22:$AG22="NT")*6+($C22:$AG22="C")*10+($C22:$AG22="A")*8+($C22:$AG22="J")*5+($C22:$AG22="E")*4+($C22:$AG22="P")*6+($C22:$AG22="R")*6) | AI22: =SUMPRODUCT($C$4:$AG$4,($C22:$AG22="M")*6+($C22:$AG22="T")*6+($C22:$AG22="D")*12+($C22:$AG22="N")*12+($C22:$AG22="NT")*6+($C22:$AG22="C")*10+($C22:$AG22="A")*8+($C22:$AG22="J")*5+($C22:$AG22="E")*4+($C22:$AG22="P")*6+($C22:$AG22="R")*6) | AJ22: =SUMPRODUCT($C$5:$AG$5,($C22:$AG22="N")*1) | AK22: =SUMPRODUCT($C$6:$AG$6,($C22:$AG22="M")*6+($C22:$AG22="T")*6+($C22:$AG22="D")*12+($C22:$AG22="N")*12+($C22:$AG22="NT")*6+($C22:$AG22="C")*10+($C22:$AG22="A")*8+($C22:$AG22="J")*5+($C22:$AG22="E")*4+($C22:$AG22="P")*6+($C22:$AG22="R")*6) | AL22: =ROUND(B22*4.43,0) | AM22: =AH22-AL22 | AN22: =SUMPRODUCT(($C22:$AF22="N")*(($D22:$AG22="M")+($D22:$AG22="E")+($D22:$AG22="C")+($D22:$AG22="D"))) | AO22: =SUMPRODUCT(($C22:$AF22="N")*($D22:$AG22="T"))
A23: Kariny | B23: 36 | D23: M | G23: D | H23: T | L23: D | M23: D | N23: T | O23: D | Q23: D | U23: D | V23: D | X23: D | AB23: D | AC23: D | AG23: D | AH23: =SUMPRODUCT(($C23:$AG23="M")*6+($C23:$AG23="T")*6+($C23:$AG23="D")*12+($C23:$AG23="N")*12+($C23:$AG23="NT")*6+($C23:$AG23="C")*10+($C23:$AG23="A")*8+($C23:$AG23="J")*5+($C23:$AG23="E")*4+($C23:$AG23="P")*6+($C23:$AG23="R")*6) | AI23: =SUMPRODUCT($C$4:$AG$4,($C23:$AG23="M")*6+($C23:$AG23="T")*6+($C23:$AG23="D")*12+($C23:$AG23="N")*12+($C23:$AG23="NT")*6+($C23:$AG23="C")*10+($C23:$AG23="A")*8+($C23:$AG23="J")*5+($C23:$AG23="E")*4+($C23:$AG23="P")*6+($C23:$AG23="R")*6) | AJ23: =SUMPRODUCT($C$5:$AG$5,($C23:$AG23="N")*1) | AK23: =SUMPRODUCT($C$6:$AG$6,($C23:$AG23="M")*6+($C23:$AG23="T")*6+($C23:$AG23="D")*12+($C23:$AG23="N")*12+($C23:$AG23="NT")*6+($C23:$AG23="C")*10+($C23:$AG23="A")*8+($C23:$AG23="J")*5+($C23:$AG23="E")*4+($C23:$AG23="P")*6+($C23:$AG23="R")*6) | AL23: =ROUND(B23*4.43,0) | AM23: =AH23-AL23 | AN23: =SUMPRODUCT(($C23:$AF23="N")*(($D23:$AG23="M")+($D23:$AG23="E")+($D23:$AG23="C")+($D23:$AG23="D"))) | AO23: =SUMPRODUCT(($C23:$AF23="N")*($D23:$AG23="T"))
A24: Mayana | B24: 36 | E24: D | G24: D | I24: N | L24: N | N24: M | O24: D | P24: M | R24: N | AH24: =SUMPRODUCT(($C24:$AG24="M")*6+($C24:$AG24="T")*6+($C24:$AG24="D")*12+($C24:$AG24="N")*12+($C24:$AG24="NT")*6+($C24:$AG24="C")*10+($C24:$AG24="A")*8+($C24:$AG24="J")*5+($C24:$AG24="E")*4+($C24:$AG24="P")*6+($C24:$AG24="R")*6) | AI24: =SUMPRODUCT($C$4:$AG$4,($C24:$AG24="M")*6+($C24:$AG24="T")*6+($C24:$AG24="D")*12+($C24:$AG24="N")*12+($C24:$AG24="NT")*6+($C24:$AG24="C")*10+($C24:$AG24="A")*8+($C24:$AG24="J")*5+($C24:$AG24="E")*4+($C24:$AG24="P")*6+($C24:$AG24="R")*6) | AJ24: =SUMPRODUCT($C$5:$AG$5,($C24:$AG24="N")*1) | AK24: =SUMPRODUCT($C$6:$AG$6,($C24:$AG24="M")*6+($C24:$AG24="T")*6+($C24:$AG24="D")*12+($C24:$AG24="N")*12+($C24:$AG24="NT")*6+($C24:$AG24="C")*10+($C24:$AG24="A")*8+($C24:$AG24="J")*5+($C24:$AG24="E")*4+($C24:$AG24="P")*6+($C24:$AG24="R")*6) | AL24: =ROUND(B24*4.43,0) | AM24: =AH24-AL24 | AN24: =SUMPRODUCT(($C24:$AF24="N")*(($D24:$AG24="M")+($D24:$AG24="E")+($D24:$AG24="C")+($D24:$AG24="D"))) | AO24: =SUMPRODUCT(($C24:$AF24="N")*($D24:$AG24="T"))
A25: Neyde | B25: 36 | F25: N | H25: N | I25: N | M25: N | O25: N | P25: N | T25: N | U25: N | V25: N | W25: N | AB25: N | AC25: N | AD25: N | AH25: =SUMPRODUCT(($C25:$AG25="M")*6+($C25:$AG25="T")*6+($C25:$AG25="D")*12+($C25:$AG25="N")*12+($C25:$AG25="NT")*6+($C25:$AG25="C")*10+($C25:$AG25="A")*8+($C25:$AG25="J")*5+($C25:$AG25="E")*4+($C25:$AG25="P")*6+($C25:$AG25="R")*6) | AI25: =SUMPRODUCT($C$4:$AG$4,($C25:$AG25="M")*6+($C25:$AG25="T")*6+($C25:$AG25="D")*12+($C25:$AG25="N")*12+($C25:$AG25="NT")*6+($C25:$AG25="C")*10+($C25:$AG25="A")*8+($C25:$AG25="J")*5+($C25:$AG25="E")*4+($C25:$AG25="P")*6+($C25:$AG25="R")*6) | AJ25: =SUMPRODUCT($C$5:$AG$5,($C25:$AG25="N")*1) | AK25: =SUMPRODUCT($C$6:$AG$6,($C25:$AG25="M")*6+($C25:$AG25="T")*6+($C25:$AG25="D")*12+($C25:$AG25="N")*12+($C25:$AG25="NT")*6+($C25:$AG25="C")*10+($C25:$AG25="A")*8+($C25:$AG25="J")*5+($C25:$AG25="E")*4+($C25:$AG25="P")*6+($C25:$AG25="R")*6) | AL25: =ROUND(B25*4.43,0) | AM25: =AH25-AL25 | AN25: =SUMPRODUCT(($C25:$AF25="N")*(($D25:$AG25="M")+($D25:$AG25="E")+($D25:$AG25="C")+($D25:$AG25="D"))) | AO25: =SUMPRODUCT(($C25:$AF25="N")*($D25:$AG25="T"))
A26: Roberta | B26: 36 | D26: D | E26: M | G26: M | H26: N | I26: T | J26: D | AF26: D | AG26: M | AH26: =SUMPRODUCT(($C26:$AG26="M")*6+($C26:$AG26="T")*6+($C26:$AG26="D")*12+($C26:$AG26="N")*12+($C26:$AG26="NT")*6+($C26:$AG26="C")*10+($C26:$AG26="A")*8+($C26:$AG26="J")*5+($C26:$AG26="E")*4+($C26:$AG26="P")*6+($C26:$AG26="R")*6) | AI26: =SUMPRODUCT($C$4:$AG$4,($C26:$AG26="M")*6+($C26:$AG26="T")*6+($C26:$AG26="D")*12+($C26:$AG26="N")*12+($C26:$AG26="NT")*6+($C26:$AG26="C")*10+($C26:$AG26="A")*8+($C26:$AG26="J")*5+($C26:$AG26="E")*4+($C26:$AG26="P")*6+($C26:$AG26="R")*6) | AJ26: =SUMPRODUCT($C$5:$AG$5,($C26:$AG26="N")*1) | AK26: =SUMPRODUCT($C$6:$AG$6,($C26:$AG26="M")*6+($C26:$AG26="T")*6+($C26:$AG26="D")*12+($C26:$AG26="N")*12+($C26:$AG26="NT")*6+($C26:$AG26="C")*10+($C26:$AG26="A")*8+($C26:$AG26="J")*5+($C26:$AG26="E")*4+($C26:$AG26="P")*6+($C26:$AG26="R")*6) | AL26: =ROUND(B26*4.43,0) | AM26: =AH26-AL26 | AN26: =SUMPRODUCT(($C26:$AF26="N")*(($D26:$AG26="M")+($D26:$AG26="E")+($D26:$AG26="C")+($D26:$AG26="D"))) | AO26: =SUMPRODUCT(($C26:$AF26="N")*($D26:$AG26="T"))
A27: LuAlice | B27: 36 | E27: N | H27: N | J27: N | O27: N | Q27: M | S27: N | V27: N | X27: N | Z27: N | AC27: N | AD27: M | AE27: N | AH27: =SUMPRODUCT(($C27:$AG27="M")*6+($C27:$AG27="T")*6+($C27:$AG27="D")*12+($C27:$AG27="N")*12+($C27:$AG27="NT")*6+($C27:$AG27="C")*10+($C27:$AG27="A")*8+($C27:$AG27="J")*5+($C27:$AG27="E")*4+($C27:$AG27="P")*6+($C27:$AG27="R")*6) | AI27: =SUMPRODUCT($C$4:$AG$4,($C27:$AG27="M")*6+($C27:$AG27="T")*6+($C27:$AG27="D")*12+($C27:$AG27="N")*12+($C27:$AG27="NT")*6+($C27:$AG27="C")*10+($C27:$AG27="A")*8+($C27:$AG27="J")*5+($C27:$AG27="E")*4+($C27:$AG27="P")*6+($C27:$AG27="R")*6) | AJ27: =SUMPRODUCT($C$5:$AG$5,($C27:$AG27="N")*1) | AK27: =SUMPRODUCT($C$6:$AG$6,($C27:$AG27="M")*6+($C27:$AG27="T")*6+($C27:$AG27="D")*12+($C27:$AG27="N")*12+($C27:$AG27="NT")*6+($C27:$AG27="C")*10+($C27:$AG27="A")*8+($C27:$AG27="J")*5+($C27:$AG27="E")*4+($C27:$AG27="P")*6+($C27:$AG27="R")*6) | AL27: =ROUND(B27*4.43,0) | AM27: =AH27-AL27 | AN27: =SUMPRODUCT(($C27:$AF27="N")*(($D27:$AG27="M")+($D27:$AG27="E")+($D27:$AG27="C")+($D27:$AG27="D"))) | AO27: =SUMPRODUCT(($C27:$AF27="N")*($D27:$AG27="T"))
A28: Amanda | B28: 30 | D28: D | E28: D | F28: D | H28: T | I28: M | J28: D | M28: M | N28: N | O28: T | P28: D | W28: D | X28: N | Z28: NT | AB28: M | AD28: D | AF28: N | AH28: =SUMPRODUCT(($C28:$AG28="M")*6+($C28:$AG28="T")*6+($C28:$AG28="D")*12+($C28:$AG28="N")*12+($C28:$AG28="NT")*6+($C28:$AG28="C")*10+($C28:$AG28="A")*8+($C28:$AG28="J")*5+($C28:$AG28="E")*4+($C28:$AG28="P")*6+($C28:$AG28="R")*6) | AI28: =SUMPRODUCT($C$4:$AG$4,($C28:$AG28="M")*6+($C28:$AG28="T")*6+($C28:$AG28="D")*12+($C28:$AG28="N")*12+($C28:$AG28="NT")*6+($C28:$AG28="C")*10+($C28:$AG28="A")*8+($C28:$AG28="J")*5+($C28:$AG28="E")*4+($C28:$AG28="P")*6+($C28:$AG28="R")*6) | AJ28: =SUMPRODUCT($C$5:$AG$5,($C28:$AG28="N")*1) | AK28: =SUMPRODUCT($C$6:$AG$6,($C28:$AG28="M")*6+($C28:$AG28="T")*6+($C28:$AG28="D")*12+($C28:$AG28="N")*12+($C28:$AG28="NT")*6+($C28:$AG28="C")*10+($C28:$AG28="A")*8+($C28:$AG28="J")*5+($C28:$AG28="E")*4+($C28:$AG28="P")*6+($C28:$AG28="R")*6) | AL28: =ROUND(B28*4.43,0) | AM28: =AH28-AL28 | AN28: =SUMPRODUCT(($C28:$AF28="N")*(($D28:$AG28="M")+($D28:$AG28="E")+($D28:$AG28="C")+($D28:$AG28="D"))) | AO28: =SUMPRODUCT(($C28:$AF28="N")*($D28:$AG28="T"))
A29: Fernando | B29: 30 | D29: M | E29: M | G29: N | I29: M | J29: M | L29: M | N29: N | P29: M | Q29: M | S29: M | U29: N | W29: M | X29: M | Z29: M | AB29: N | AD29: M | AE29: M | AG29: M | AH29: =SUMPRODUCT(($C29:$AG29="M")*6+($C29:$AG29="T")*6+($C29:$AG29="D")*12+($C29:$AG29="N")*12+($C29:$AG29="NT")*6+($C29:$AG29="C")*10+($C29:$AG29="A")*8+($C29:$AG29="J")*5+($C29:$AG29="E")*4+($C29:$AG29="P")*6+($C29:$AG29="R")*6) | AI29: =SUMPRODUCT($C$4:$AG$4,($C29:$AG29="M")*6+($C29:$AG29="T")*6+($C29:$AG29="D")*12+($C29:$AG29="N")*12+($C29:$AG29="NT")*6+($C29:$AG29="C")*10+($C29:$AG29="A")*8+($C29:$AG29="J")*5+($C29:$AG29="E")*4+($C29:$AG29="P")*6+($C29:$AG29="R")*6) | AJ29: =SUMPRODUCT($C$5:$AG$5,($C29:$AG29="N")*1) | AK29: =SUMPRODUCT($C$6:$AG$6,($C29:$AG29="M")*6+($C29:$AG29="T")*6+($C29:$AG29="D")*12+($C29:$AG29="N")*12+($C29:$AG29="NT")*6+($C29:$AG29="C")*10+($C29:$AG29="A")*8+($C29:$AG29="J")*5+($C29:$AG29="E")*4+($C29:$AG29="P")*6+($C29:$AG29="R")*6) | AL29: =ROUND(B29*4.43,0) | AM29: =AH29-AL29 | AN29: =SUMPRODUCT(($C29:$AF29="N")*(($D29:$AG29="M")+($D29:$AG29="E")+($D29:$AG29="C")+($D29:$AG29="D"))) | AO29: =SUMPRODUCT(($C29:$AF29="N")*($D29:$AG29="T"))
A30: João | B30: 30 | E30: N | H30: N | I30: T | K30: T | O30: N | R30: N | T30: D | V30: N | W30: T | AA30: N | AC30: N | AD30: T | AH30: =SUMPRODUCT(($C30:$AG30="M")*6+($C30:$AG30="T")*6+($C30:$AG30="D")*12+($C30:$AG30="N")*12+($C30:$AG30="NT")*6+($C30:$AG30="C")*10+($C30:$AG30="A")*8+($C30:$AG30="J")*5+($C30:$AG30="E")*4+($C30:$AG30="P")*6+($C30:$AG30="R")*6) | AI30: =SUMPRODUCT($C$4:$AG$4,($C30:$AG30="M")*6+($C30:$AG30="T")*6+($C30:$AG30="D")*12+($C30:$AG30="N")*12+($C30:$AG30="NT")*6+($C30:$AG30="C")*10+($C30:$AG30="A")*8+($C30:$AG30="J")*5+($C30:$AG30="E")*4+($C30:$AG30="P")*6+($C30:$AG30="R")*6) | AJ30: =SUMPRODUCT($C$5:$AG$5,($C30:$AG30="N")*1) | AK30: =SUMPRODUCT($C$6:$AG$6,($C30:$AG30="M")*6+($C30:$AG30="T")*6+($C30:$AG30="D")*12+($C30:$AG30="N")*12+($C30:$AG30="NT")*6+($C30:$AG30="C")*10+($C30:$AG30="A")*8+($C30:$AG30="J")*5+($C30:$AG30="E")*4+($C30:$AG30="P")*6+($C30:$AG30="R")*6) | AL30: =ROUND(B30*4.43,0) | AM30: =AH30-AL30 | AN30: =SUMPRODUCT(($C30:$AF30="N")*(($D30:$AG30="M")+($D30:$AG30="E")+($D30:$AG30="C")+($D30:$AG30="D"))) | AO30: =SUMPRODUCT(($C30:$AF30="N")*($D30:$AG30="T"))
A31: JuCoutinho | B31: 30 | D31: M | E31: N | G31: T | H31: D | I31: D | M31: T | N31: D | P31: T | R31: M | S31: N | U31: D | V31: M | W31: D | Y31: M | AB31: D | AD31: D | AF31: M | AG31: M | AH31: =SUMPRODUCT(($C31:$AG31="M")*6+($C31:$AG31="T")*6+($C31:$AG31="D")*12+($C31:$AG31="N")*12+($C31:$AG31="NT")*6+($C31:$AG31="C")*10+($C31:$AG31="A")*8+($C31:$AG31="J")*5+($C31:$AG31="E")*4+($C31:$AG31="P")*6+($C31:$AG31="R")*6) | AI31: =SUMPRODUCT($C$4:$AG$4,($C31:$AG31="M")*6+($C31:$AG31="T")*6+($C31:$AG31="D")*12+($C31:$AG31="N")*12+($C31:$AG31="NT")*6+($C31:$AG31="C")*10+($C31:$AG31="A")*8+($C31:$AG31="J")*5+($C31:$AG31="E")*4+($C31:$AG31="P")*6+($C31:$AG31="R")*6) | AJ31: =SUMPRODUCT($C$5:$AG$5,($C31:$AG31="N")*1) | AK31: =SUMPRODUCT($C$6:$AG$6,($C31:$AG31="M")*6+($C31:$AG31="T")*6+($C31:$AG31="D")*12+($C31:$AG31="N")*12+($C31:$AG31="NT")*6+($C31:$AG31="C")*10+($C31:$AG31="A")*8+($C31:$AG31="J")*5+($C31:$AG31="E")*4+($C31:$AG31="P")*6+($C31:$AG31="R")*6) | AL31: =ROUND(B31*4.43,0) | AM31: =AH31-AL31 | AN31: =SUMPRODUCT(($C31:$AF31="N")*(($D31:$AG31="M")+($D31:$AG31="E")+($D31:$AG31="C")+($D31:$AG31="D"))) | AO31: =SUMPRODUCT(($C31:$AF31="N")*($D31:$AG31="T"))
A32: LeLemos | B32: 30 | D32: N | F32: M | G32: N | K32: N | M32: D | N32: D | Q32: T | T32: M | U32: N | Z32: M | AA32: M | AD32: N | AF32: T | AH32: =SUMPRODUCT(($C32:$AG32="M")*6+($C32:$AG32="T")*6+($C32:$AG32="D")*12+($C32:$AG32="N")*12+($C32:$AG32="NT")*6+($C32:$AG32="C")*10+($C32:$AG32="A")*8+($C32:$AG32="J")*5+($C32:$AG32="E")*4+($C32:$AG32="P")*6+($C32:$AG32="R")*6) | AI32: =SUMPRODUCT($C$4:$AG$4,($C32:$AG32="M")*6+($C32:$AG32="T")*6+($C32:$AG32="D")*12+($C32:$AG32="N")*12+($C32:$AG32="NT")*6+($C32:$AG32="C")*10+($C32:$AG32="A")*8+($C32:$AG32="J")*5+($C32:$AG32="E")*4+($C32:$AG32="P")*6+($C32:$AG32="R")*6) | AJ32: =SUMPRODUCT($C$5:$AG$5,($C32:$AG32="N")*1) | AK32: =SUMPRODUCT($C$6:$AG$6,($C32:$AG32="M")*6+($C32:$AG32="T")*6+($C32:$AG32="D")*12+($C32:$AG32="N")*12+($C32:$AG32="NT")*6+($C32:$AG32="C")*10+($C32:$AG32="A")*8+($C32:$AG32="J")*5+($C32:$AG32="E")*4+($C32:$AG32="P")*6+($C32:$AG32="R")*6) | AL32: =ROUND(B32*4.43,0) | AM32: =AH32-AL32 | AN32: =SUMPRODUCT(($C32:$AF32="N")*(($D32:$AG32="M")+($D32:$AG32="E")+($D32:$AG32="C")+($D32:$AG32="D"))) | AO32: =SUMPRODUCT(($C32:$AF32="N")*($D32:$AG32="T"))
A33: Leomara | B33: 24 | AH33: =SUMPRODUCT(($C33:$AG33="M")*6+($C33:$AG33="T")*6+($C33:$AG33="D")*12+($C33:$AG33="N")*12+($C33:$AG33="NT")*6+($C33:$AG33="C")*10+($C33:$AG33="A")*8+($C33:$AG33="J")*5+($C33:$AG33="E")*4+($C33:$AG33="P")*6+($C33:$AG33="R")*6) | AI33: =SUMPRODUCT($C$4:$AG$4,($C33:$AG33="M")*6+($C33:$AG33="T")*6+($C33:$AG33="D")*12+($C33:$AG33="N")*12+($C33:$AG33="NT")*6+($C33:$AG33="C")*10+($C33:$AG33="A")*8+($C33:$AG33="J")*5+($C33:$AG33="E")*4+($C33:$AG33="P")*6+($C33:$AG33="R")*6) | AJ33: =SUMPRODUCT($C$5:$AG$5,($C33:$AG33="N")*1) | AK33: =SUMPRODUCT($C$6:$AG$6,($C33:$AG33="M")*6+($C33:$AG33="T")*6+($C33:$AG33="D")*12+($C33:$AG33="N")*12+($C33:$AG33="NT")*6+($C33:$AG33="C")*10+($C33:$AG33="A")*8+($C33:$AG33="J")*5+($C33:$AG33="E")*4+($C33:$AG33="P")*6+($C33:$AG33="R")*6) | AL33: =ROUND(B33*4.43,0) | AM33: =AH33-AL33 | AN33: =SUMPRODUCT(($C33:$AF33="N")*(($D33:$AG33="M")+($D33:$AG33="E")+($D33:$AG33="C")+($D33:$AG33="D"))) | AO33: =SUMPRODUCT(($C33:$AF33="N")*($D33:$AG33="T"))
A34: Marilia | B34: 30 | D34: D | I34: D | L34: D | M34: M | O34: D | P34: M | R34: N | W34: D | X34: M | AA34: D | AC34: D | AD34: M | AE34: D | AH34: =SUMPRODUCT(($C34:$AG34="M")*6+($C34:$AG34="T")*6+($C34:$AG34="D")*12+($C34:$AG34="N")*12+($C34:$AG34="NT")*6+($C34:$AG34="C")*10+($C34:$AG34="A")*8+($C34:$AG34="J")*5+($C34:$AG34="E")*4+($C34:$AG34="P")*6+($C34:$AG34="R")*6) | AI34: =SUMPRODUCT($C$4:$AG$4,($C34:$AG34="M")*6+($C34:$AG34="T")*6+($C34:$AG34="D")*12+($C34:$AG34="N")*12+($C34:$AG34="NT")*6+($C34:$AG34="C")*10+($C34:$AG34="A")*8+($C34:$AG34="J")*5+($C34:$AG34="E")*4+($C34:$AG34="P")*6+($C34:$AG34="R")*6) | AJ34: =SUMPRODUCT($C$5:$AG$5,($C34:$AG34="N")*1) | AK34: =SUMPRODUCT($C$6:$AG$6,($C34:$AG34="M")*6+($C34:$AG34="T")*6+($C34:$AG34="D")*12+($C34:$AG34="N")*12+($C34:$AG34="NT")*6+($C34:$AG34="C")*10+($C34:$AG34="A")*8+($C34:$AG34="J")*5+($C34:$AG34="E")*4+($C34:$AG34="P")*6+($C34:$AG34="R")*6) | AL34: =ROUND(B34*4.43,0) | AM34: =AH34-AL34 | AN34: =SUMPRODUCT(($C34:$AF34="N")*(($D34:$AG34="M")+($D34:$AG34="E")+($D34:$AG34="C")+($D34:$AG34="D"))) | AO34: =SUMPRODUCT(($C34:$AF34="N")*($D34:$AG34="T"))
A35: Raylander | B35: 30 | F35: D | G35: N | I35: D | L35: M | O35: M | Q35: N | S35: N | U35: N | W35: T | Y35: N | AB35: N | AC35: M | AE35: N | AH35: =SUMPRODUCT(($C35:$AG35="M")*6+($C35:$AG35="T")*6+($C35:$AG35="D")*12+($C35:$AG35="N")*12+($C35:$AG35="NT")*6+($C35:$AG35="C")*10+($C35:$AG35="A")*8+($C35:$AG35="J")*5+($C35:$AG35="E")*4+($C35:$AG35="P")*6+($C35:$AG35="R")*6) | AI35: =SUMPRODUCT($C$4:$AG$4,($C35:$AG35="M")*6+($C35:$AG35="T")*6+($C35:$AG35="D")*12+($C35:$AG35="N")*12+($C35:$AG35="NT")*6+($C35:$AG35="C")*10+($C35:$AG35="A")*8+($C35:$AG35="J")*5+($C35:$AG35="E")*4+($C35:$AG35="P")*6+($C35:$AG35="R")*6) | AJ35: =SUMPRODUCT($C$5:$AG$5,($C35:$AG35="N")*1) | AK35: =SUMPRODUCT($C$6:$AG$6,($C35:$AG35="M")*6+($C35:$AG35="T")*6+($C35:$AG35="D")*12+($C35:$AG35="N")*12+($C35:$AG35="NT")*6+($C35:$AG35="C")*10+($C35:$AG35="A")*8+($C35:$AG35="J")*5+($C35:$AG35="E")*4+($C35:$AG35="P")*6+($C35:$AG35="R")*6) | AL35: =ROUND(B35*4.43,0) | AM35: =AH35-AL35 | AN35: =SUMPRODUCT(($C35:$AF35="N")*(($D35:$AG35="M")+($D35:$AG35="E")+($D35:$AG35="C")+($D35:$AG35="D"))) | AO35: =SUMPRODUCT(($C35:$AF35="N")*($D35:$AG35="T"))
A36: Ricardo | B36: 30 | D36: D | E36: T | F36: T | H36: N | J36: M | K36: D | O36: NT | R36: M | S36: D | T36: M | V36: N | X36: M | Y36: D | AB36: M | AC36: N | AF36: D | AH36: =SUMPRODUCT(($C36:$AG36="M")*6+($C36:$AG36="T")*6+($C36:$AG36="D")*12+($C36:$AG36="N")*12+($C36:$AG36="NT")*6+($C36:$AG36="C")*10+($C36:$AG36="A")*8+($C36:$AG36="J")*5+($C36:$AG36="E")*4+($C36:$AG36="P")*6+($C36:$AG36="R")*6) | AI36: =SUMPRODUCT($C$4:$AG$4,($C36:$AG36="M")*6+($C36:$AG36="T")*6+($C36:$AG36="D")*12+($C36:$AG36="N")*12+($C36:$AG36="NT")*6+($C36:$AG36="C")*10+($C36:$AG36="A")*8+($C36:$AG36="J")*5+($C36:$AG36="E")*4+($C36:$AG36="P")*6+($C36:$AG36="R")*6) | AJ36: =SUMPRODUCT($C$5:$AG$5,($C36:$AG36="N")*1) | AK36: =SUMPRODUCT($C$6:$AG$6,($C36:$AG36="M")*6+($C36:$AG36="T")*6+($C36:$AG36="D")*12+($C36:$AG36="N")*12+($C36:$AG36="NT")*6+($C36:$AG36="C")*10+($C36:$AG36="A")*8+($C36:$AG36="J")*5+($C36:$AG36="E")*4+($C36:$AG36="P")*6+($C36:$AG36="R")*6) | AL36: =ROUND(B36*4.43,0) | AM36: =AH36-AL36 | AN36: =SUMPRODUCT(($C36:$AF36="N")*(($D36:$AG36="M")+($D36:$AG36="E")+($D36:$AG36="C")+($D36:$AG36="D"))) | AO36: =SUMPRODUCT(($C36:$AF36="N")*($D36:$AG36="T"))
A37: Rosana | B37: 30 | F37: N | H37: D | J37: D | K37: M | O37: D | R37: M | T37: N | U37: M | W37: M | X37: T | Y37: M | Z37: T | AB37: M | AC37: D | AE37: D | AH37: =SUMPRODUCT(($C37:$AG37="M")*6+($C37:$AG37="T")*6+($C37:$AG37="D")*12+($C37:$AG37="N")*12+($C37:$AG37="NT")*6+($C37:$AG37="C")*10+($C37:$AG37="A")*8+($C37:$AG37="J")*5+($C37:$AG37="E")*4+($C37:$AG37="P")*6+($C37:$AG37="R")*6) | AI37: =SUMPRODUCT($C$4:$AG$4,($C37:$AG37="M")*6+($C37:$AG37="T")*6+($C37:$AG37="D")*12+($C37:$AG37="N")*12+($C37:$AG37="NT")*6+($C37:$AG37="C")*10+($C37:$AG37="A")*8+($C37:$AG37="J")*5+($C37:$AG37="E")*4+($C37:$AG37="P")*6+($C37:$AG37="R")*6) | AJ37: =SUMPRODUCT($C$5:$AG$5,($C37:$AG37="N")*1) | AK37: =SUMPRODUCT($C$6:$AG$6,($C37:$AG37="M")*6+($C37:$AG37="T")*6+($C37:$AG37="D")*12+($C37:$AG37="N")*12+($C37:$AG37="NT")*6+($C37:$AG37="C")*10+($C37:$AG37="A")*8+($C37:$AG37="J")*5+($C37:$AG37="E")*4+($C37:$AG37="P")*6+($C37:$AG37="R")*6) | AL37: =ROUND(B37*4.43,0) | AM37: =AH37-AL37 | AN37: =SUMPRODUCT(($C37:$AF37="N")*(($D37:$AG37="M")+($D37:$AG37="E")+($D37:$AG37="C")+($D37:$AG37="D"))) | AO37: =SUMPRODUCT(($C37:$AF37="N")*($D37:$AG37="T"))
A38: AnaSeverino | B38: 24 | AH38: =SUMPRODUCT(($C38:$AG38="M")*6+($C38:$AG38="T")*6+($C38:$AG38="D")*12+($C38:$AG38="N")*12+($C38:$AG38="NT")*6+($C38:$AG38="C")*10+($C38:$AG38="A")*8+($C38:$AG38="J")*5+($C38:$AG38="E")*4+($C38:$AG38="P")*6+($C38:$AG38="R")*6) | AI38: =SUMPRODUCT($C$4:$AG$4,($C38:$AG38="M")*6+($C38:$AG38="T")*6+($C38:$AG38="D")*12+($C38:$AG38="N")*12+($C38:$AG38="NT")*6+($C38:$AG38="C")*10+($C38:$AG38="A")*8+($C38:$AG38="J")*5+($C38:$AG38="E")*4+($C38:$AG38="P")*6+($C38:$AG38="R")*6) | AJ38: =SUMPRODUCT($C$5:$AG$5,($C38:$AG38="N")*1) | AK38: =SUMPRODUCT($C$6:$AG$6,($C38:$AG38="M")*6+($C38:$AG38="T")*6+($C38:$AG38="D")*12+($C38:$AG38="N")*12+($C38:$AG38="NT")*6+($C38:$AG38="C")*10+($C38:$AG38="A")*8+($C38:$AG38="J")*5+($C38:$AG38="E")*4+($C38:$AG38="P")*6+($C38:$AG38="R")*6) | AL38: =ROUND(B38*4.43,0) | AM38: =AH38-AL38 | AN38: =SUMPRODUCT(($C38:$AF38="N")*(($D38:$AG38="M")+($D38:$AG38="E")+($D38:$AG38="C")+($D38:$AG38="D"))) | AO38: =SUMPRODUCT(($C38:$AF38="N")*($D38:$AG38="T"))
A39: Anna | B39: 24 | E39: N | G39: T | H39: M | K39: M | L39: T | N39: T | O39: M | Q39: T | R39: M | V39: M | W39: D | Y39: M | AC39: M | AE39: M | AG39: N | AH39: =SUMPRODUCT(($C39:$AG39="M")*6+($C39:$AG39="T")*6+($C39:$AG39="D")*12+($C39:$AG39="N")*12+($C39:$AG39="NT")*6+($C39:$AG39="C")*10+($C39:$AG39="A")*8+($C39:$AG39="J")*5+($C39:$AG39="E")*4+($C39:$AG39="P")*6+($C39:$AG39="R")*6) | AI39: =SUMPRODUCT($C$4:$AG$4,($C39:$AG39="M")*6+($C39:$AG39="T")*6+($C39:$AG39="D")*12+($C39:$AG39="N")*12+($C39:$AG39="NT")*6+($C39:$AG39="C")*10+($C39:$AG39="A")*8+($C39:$AG39="J")*5+($C39:$AG39="E")*4+($C39:$AG39="P")*6+($C39:$AG39="R")*6) | AJ39: =SUMPRODUCT($C$5:$AG$5,($C39:$AG39="N")*1) | AK39: =SUMPRODUCT($C$6:$AG$6,($C39:$AG39="M")*6+($C39:$AG39="T")*6+($C39:$AG39="D")*12+($C39:$AG39="N")*12+($C39:$AG39="NT")*6+($C39:$AG39="C")*10+($C39:$AG39="A")*8+($C39:$AG39="J")*5+($C39:$AG39="E")*4+($C39:$AG39="P")*6+($C39:$AG39="R")*6) | AL39: =ROUND(B39*4.43,0) | AM39: =AH39-AL39 | AN39: =SUMPRODUCT(($C39:$AF39="N")*(($D39:$AG39="M")+($D39:$AG39="E")+($D39:$AG39="C")+($D39:$AG39="D"))) | AO39: =SUMPRODUCT(($C39:$AF39="N")*($D39:$AG39="T"))
A40: Ariadne | B40: 24 | AH40: =SUMPRODUCT(($C40:$AG40="M")*6+($C40:$AG40="T")*6+($C40:$AG40="D")*12+($C40:$AG40="N")*12+($C40:$AG40="NT")*6+($C40:$AG40="C")*10+($C40:$AG40="A")*8+($C40:$AG40="J")*5+($C40:$AG40="E")*4+($C40:$AG40="P")*6+($C40:$AG40="R")*6) | AI40: =SUMPRODUCT($C$4:$AG$4,($C40:$AG40="M")*6+($C40:$AG40="T")*6+($C40:$AG40="D")*12+($C40:$AG40="N")*12+($C40:$AG40="NT")*6+($C40:$AG40="C")*10+($C40:$AG40="A")*8+($C40:$AG40="J")*5+($C40:$AG40="E")*4+($C40:$AG40="P")*6+($C40:$AG40="R")*6) | AJ40: =SUMPRODUCT($C$5:$AG$5,($C40:$AG40="N")*1) | AK40: =SUMPRODUCT($C$6:$AG$6,($C40:$AG40="M")*6+($C40:$AG40="T")*6+($C40:$AG40="D")*12+($C40:$AG40="N")*12+($C40:$AG40="NT")*6+($C40:$AG40="C")*10+($C40:$AG40="A")*8+($C40:$AG40="J")*5+($C40:$AG40="E")*4+($C40:$AG40="P")*6+($C40:$AG40="R")*6) | AL40: =ROUND(B40*4.43,0) | AM40: =AH40-AL40 | AN40: =SUMPRODUCT(($C40:$AF40="N")*(($D40:$AG40="M")+($D40:$AG40="E")+($D40:$AG40="C")+($D40:$AG40="D"))) | AO40: =SUMPRODUCT(($C40:$AF40="N")*($D40:$AG40="T"))
...

Sheet FEV
A1: fevereiro · 2026 | C1: códigos Senior (códigos antigos 110/82/83)
C2: 1 | D2: 2 | E2: 3 | F2: 4 | G2: 5 | H2: 6 | I2: 7 | J2: 8 | K2: 9 | L2: 10 | M2: 11 | N2: 12 | O2: 13 | P2: 14 | Q2: 15 | R2: 16 | S2: 17 | T2: 18 | U2: 19 | V2: 20 | W2: 21 | X2: 22 | Y2: 23 | Z2: 24 | AA2: 25 | AB2: 26 | AC2: 27 | AD2: 28
C3: dom | D3: seg | E3: ter | F3: qua | G3: qui | H3: sex | I3: sáb | J3: dom | K3: seg | L3: ter | M3: qua | N3: qui | O3: sex | P3: sáb | Q3: dom | R3: carn | S3: carn | T3: qua | U3: qui | V3: sex | W3: sáb | X3: dom | Y3: seg | Z3: ter | AA3: qua | AB3: qui | AC3: sex | AD3: sáb
A4: máscara fds | C4: 1 | D4: 0 | E4: 0 | F4: 0 | G4: 0 | H4: 0 | I4: 1 | J4: 1 | K4: 0 | L4: 0 | M4: 0 | N4: 0 | O4: 0 | P4: 1 | Q4: 1 | R4: 0 | S4: 0 | T4: 0 | U4: 0 | V4: 0 | W4: 1 | X4: 1 | Y4: 0 | Z4: 0 | AA4: 0 | AB4: 0 | AC4: 0 | AD4: 1
A5: máscara sexta | C5: 0 | D5: 0 | E5: 0 | F5: 0 | G5: 0 | H5: 1 | I5: 0 | J5: 0 | K5: 0 | L5: 0 | M5: 0 | N5: 0 | O5: 1 | P5: 0 | Q5: 0 | R5: 0 | S5: 0 | T5: 0 | U5: 0 | V5: 1 | W5: 0 | X5: 0 | Y5: 0 | Z5: 0 | AA5: 0 | AB5: 0 | AC5: 1 | AD5: 0
A6: máscara feriado | C6: 0 | D6: 0 | E6: 0 | F6: 0 | G6: 0 | H6: 0 | I6: 0 | J6: 0 | K6: 0 | L6: 0 | M6: 0 | N6: 0 | O6: 0 | P6: 0 | Q6: 0 | R6: 1 | S6: 1 | T6: 0 | U6: 0 | V6: 0 | W6: 0 | X6: 0 | Y6: 0 | Z6: 0 | AA6: 0 | AB6: 0 | AC6: 0 | AD6: 0
A7: médico | B7: CH | AH7: CH mês | AI7: fds | AJ7: SxN | AK7: feriado | AL7: meta | AM7: saldo | AN7: 18h⚠ | AO7: N→T
A8: Fred | B8: 36 | K8: C | L8: C | M8: M | N8: M | O8: C | P8: M | Q8: M | R8: C | S8: C | T8: M | U8: M | V8: M | Y8: C | Z8: C | AA8: M | AB8: M | AC8: C | AD8: M | AH8: =SUMPRODUCT(($C8:$AG8="M")*6+($C8:$AG8="T")*6+($C8:$AG8="D")*12+($C8:$AG8="N")*12+($C8:$AG8="NT")*6+($C8:$AG8="C")*10+($C8:$AG8="A")*8+($C8:$AG8="J")*5+($C8:$AG8="E")*4+($C8:$AG8="P")*6+($C8:$AG8="R")*6) | AI8: =SUMPRODUCT($C$4:$AG$4,($C8:$AG8="M")*6+($C8:$AG8="T")*6+($C8:$AG8="D")*12+($C8:$AG8="N")*12+($C8:$AG8="NT")*6+($C8:$AG8="C")*10+($C8:$AG8="A")*8+($C8:$AG8="J")*5+($C8:$AG8="E")*4+($C8:$AG8="P")*6+($C8:$AG8="R")*6) | AJ8: =SUMPRODUCT($C$5:$AG$5,($C8:$AG8="N")*1) | AK8: =SUMPRODUCT($C$6:$AG$6,($C8:$AG8="M")*6+($C8:$AG8="T")*6+($C8:$AG8="D")*12+($C8:$AG8="N")*12+($C8:$AG8="NT")*6+($C8:$AG8="C")*10+($C8:$AG8="A")*8+($C8:$AG8="J")*5+($C8:$AG8="E")*4+($C8:$AG8="P")*6+($C8:$AG8="R")*6) | AL8: =ROUND(B8*4.0,0) | AM8: =AH8-AL8 | AN8: =SUMPRODUCT(($C8:$AF8="N")*(($D8:$AG8="M")+($D8:$AG8="E")+($D8:$AG8="C")+($D8:$AG8="D"))) | AO8: =SUMPRODUCT(($C8:$AF8="N")*($D8:$AG8="T"))
A9: Milena | B9: 36 | D9: M | E9: M | F9: M | G9: C | H9: C | I9: M | J9: M | K9: M | L9: M | M9: M | N9: C | O9: M | P9: M | Q9: M | R9: M | S9: M | T9: M | U9: C | V9: M | Y9: M | Z9: M | AA9: M | AB9: C | AC9: M | AD9: M | AH9: =SUMPRODUCT(($C9:$AG9="M")*6+($C9:$AG9="T")*6+($C9:$AG9="D")*12+($C9:$AG9="N")*12+($C9:$AG9="NT")*6+($C9:$AG9="C")*10+($C9:$AG9="A")*8+($C9:$AG9="J")*5+($C9:$AG9="E")*4+($C9:$AG9="P")*6+($C9:$AG9="R")*6) | AI9: =SUMPRODUCT($C$4:$AG$4,($C9:$AG9="M")*6+($C9:$AG9="T")*6+($C9:$AG9="D")*12+($C9:$AG9="N")*12+($C9:$AG9="NT")*6+($C9:$AG9="C")*10+($C9:$AG9="A")*8+($C9:$AG9="J")*5+($C9:$AG9="E")*4+($C9:$AG9="P")*6+($C9:$AG9="R")*6) | AJ9: =SUMPRODUCT($C$5:$AG$5,($C9:$AG9="N")*1) | AK9: =SUMPRODUCT($C$6:$AG$6,($C9:$AG9="M")*6+($C9:$AG9="T")*6+($C9:$AG9="D")*12+($C9:$AG9="N")*12+($C9:$AG9="NT")*6+($C9:$AG9="C")*10+($C9:$AG9="A")*8+($C9:$AG9="J")*5+($C9:$AG9="E")*4+($C9:$AG9="P")*6+($C9:$AG9="R")*6) | AL9: =ROUND(B9*4.0,0) | AM9: =AH9-AL9 | AN9: =SUMPRODUCT(($C9:$AF9="N")*(($D9:$AG9="M")+($D9:$AG9="E")+($D9:$AG9="C")+($D9:$AG9="D"))) | AO9: =SUMPRODUCT(($C9:$AF9="N")*($D9:$AG9="T"))
A10: Pabdo | B10: 36 | AH10: =SUMPRODUCT(($C10:$AG10="M")*6+($C10:$AG10="T")*6+($C10:$AG10="D")*12+($C10:$AG10="N")*12+($C10:$AG10="NT")*6+($C10:$AG10="C")*10+($C10:$AG10="A")*8+($C10:$AG10="J")*5+($C10:$AG10="E")*4+($C10:$AG10="P")*6+($C10:$AG10="R")*6) | AI10: =SUMPRODUCT($C$4:$AG$4,($C10:$AG10="M")*6+($C10:$AG10="T")*6+($C10:$AG10="D")*12+($C10:$AG10="N")*12+($C10:$AG10="NT")*6+($C10:$AG10="C")*10+($C10:$AG10="A")*8+($C10:$AG10="J")*5+($C10:$AG10="E")*4+($C10:$AG10="P")*6+($C10:$AG10="R")*6) | AJ10: =SUMPRODUCT($C$5:$AG$5,($C10:$AG10="N")*1) | AK10: =SUMPRODUCT($C$6:$AG$6,($C10:$AG10="M")*6+($C10:$AG10="T")*6+($C10:$AG10="D")*12+($C10:$AG10="N")*12+($C10:$AG10="NT")*6+($C10:$AG10="C")*10+($C10:$AG10="A")*8+($C10:$AG10="J")*5+($C10:$AG10="E")*4+($C10:$AG10="P")*6+($C10:$AG10="R")*6) | AL10: =ROUND(B10*4.0,0) | AM10: =AH10-AL10 | AN10: =SUMPRODUCT(($C10:$AF10="N")*(($D10:$AG10="M")+($D10:$AG10="E")+($D10:$AG10="C")+($D10:$AG10="D"))) | AO10: =SUMPRODUCT(($C10:$AF10="N")*($D10:$AG10="T"))
